Workbook

Sheet IA Marks
BA1: Formative % : | BG1: 40 | BH1: Attainment Level 1: | BI1: % of maximum marks | BJ1: LEVEL 1: | BK1: 40
B2: % of students scoring greater than or equal to | BA2: Summative % : | BG2: 60 | BH2: Attainment Level 2: | BJ2: LEVEL 2: | BK2: 50
A3: IF(D8<IA!BA1,0,IF(D8>=IA!BA3,3,IF(D8>=IA!BA2,2,1))) | D3: Department of Computer Science and Engineering - Cyber Security Program | BA3: Direct : | BG3: 80 | BH3: Attainment Level 3: | BJ3: LEVEL 3: | BK3: 60
B4: Kiran 200 | D4: Academic Year : | N4: 2024-25 | Z4: Semester: | AC4: 7 | AG4: DIV: | AJ4: Course Code: | AP4: S23CY304PC | AS4: Student Count | AY4: 109 | BA4: Indirect : | BG4: 20
D5: Name of Course Teacher: | J5: Dr. Kiran B. Malagi | U5: Set Target: | Z5: 50 | AA5: Course Name: | AI5: Computer Organization and Architecture | BA5: Assignment | BN5: =BH1&BK1&""&BL1&""&AK5&BI1 -> Attainment Level 1: 40% of maximum marks
A6: USN | B6: Name | D6: IA-1 | U6: IA-2 | AK6: IA-1 | AL6: IA-1 | AM6: IA-1 | AN6: IA-2 | AO6: IA-2 | AP6: IA-2 | BA6: CIA1 | BB6: CIA2 | BC6: CIA3 | BD6: CIA4 | BE6: CIA5 | BF6: CIA6 | BG6: CIA7 | BN6: =BH2&BK2&""&BL1&""&AK5&BI1 -> Attainment Level 2: 50% of maximum marks
C7: CO Mapped | D7: 2 | E7: 2 | F7: 3 | G7: 3 | H7: 2 | I7: 2 | J7: 1 | K7: 1 | L7: 2 | M7: 2 | N7: 3 | O7: 3 | P7: 5 | Q7: 5 | U7: 3 | W7: 2 | X7: 2 | Y7: 3 | AA7: 4 | AC7: 3 | AE7: 3 | AG7: 5 | BA7: 1 | BB7: 2 | BC7: 3 | BD7: 4 | BE7: 5 | BN7: =BH3&BK3&""&BL1&""&AK5&BI1 -> Attainment Level 3: 60% of maximum marks
C8: Q. No. | D8: 1a | E8: 1b | F8: 2a | G8: 2b | H8: 3a | I8: 3b | J8: 4a | K8: 4b | L8: 5a | M8: 5b | N8: 6a | O8: 6b | U8: 1a | V8: 1b | W8: 2a | X8: 2b | Y8: 3a | Z8: 3b | AA8: 4a | AB8: 4b | AC8: 5a | AD8: 5b | AE8: 6a | AF8: 6b | AK8: OBJ (10) | AL8: ASSIGN/SPA (05) | AM8: TOTAL MARKS (35) | AN8: OBJ (10) | AO8: ASSIGN/SPA (05) | AP8: TOTAL MARKS (35) | BA8: 1 | BB8: 2 | BC8: 3 | BD8: 4 | BE8: 5 | BF8: 6 | BG8: 7 | BI8: CO1 | BL8: CO2 | BO8: CO3 | BR8: CO4 | BU8: CO5 | BX8: CO6
C9: Max. Marks | D9: 5 | F9: 5 | H9: 5 | J9: 2.5 | K9: 2.5 | L9: 3 | M9: 2 | N9: 5 | O9: 0 | P9: 5 | Q9: 5 | U9: 5 | W9: 3 | X9: 2 | Y9: 5 | AA9: 5 | AC9: 5 | AE9: 5 | AG9: 5 | AK9: 10 | AL9: 5 | AM9: 35 | AN9: 10 | AO9: 5 | AP9: 35 | BA9: 10 | BB9: 10 | BC9: 10 | BD9: 10 | BE9: 10 | BI9: Level | BK9: =IFERROR(IF(BK10<BK1,0,IF(BK10>=BK3,3,IF(BK10>=BK2,2,1))),0) -> 3 | BL9: Level | BN9: =IFERROR(IF(BN10<BK1,0,IF(BN10>=BK3,3,IF(BN10>=BK2,2,1))),0) -> 3 | BO9: Level | BQ9: =IFERROR(IF(BQ10<BK1,0,IF(BQ10>=BK3,3,IF(BQ10>=BK2,2,1))),0) -> 3 | BR9: Level | BT9: =IFERROR(IF(BT10<BK1,0,IF(BT10>=BK3,3,IF(BT10>=BK2,2,1))),0) -> 3 | BU9: Level | BW9: =IFERROR(IF(BW10<BK1,0,IF(BW10>=BK3,3,IF(BW10>=BK2,2,1))),0) -> 3 | BX9: Level | BZ9: =IFERROR(IF(BZ10<BK1,0,IF(BZ10>=BK3,3,IF(BZ10>=BK2,2,1))),0) -> 0
D10: Formative Assessment Tool | BI10: Percentage | BK10: =IFERROR(BK11/BI11*100,0) -> 85.123967 | BL10: Percentage | BN10: =IFERROR(BN11/BL11*100,0) -> 89.256198 | BO10: Percentage | BQ10: =IFERROR(BQ11/BO11*100,0) -> 86.77686 | BR10: Percentage | BT10: =IFERROR(BT11/BR11*100,0) -> 80.991736 | BU10: Percentage | BW10: =IFERROR(BW11/BU11*100,0) -> 78.512397 | BX10: Percentage | BZ10: =IFERROR(BZ11/BX11*100,0) -> 0
BI11: =COUNTIF(BJ13:BJ200,">"&0) -> 121 | BK11: =COUNTIF(BK13:BK200,">="&Z5) -> 103 | BL11: =COUNTIF(BM13:BM200,">"&0) -> 121 | BN11: =COUNTIF(BN13:BN200,">="&Z5) -> 108 | BO11: =COUNTIF(BP13:BP200,">"&0) -> 121 | BQ11: =COUNTIF(BQ13:BQ200,">="&Z5) -> 105 | BR11: =COUNTIF(BS13:BS200,">"&0) -> 121 | BT11: =COUNTIF(BT13:BT200,">="&Z5) -> 98 | BU11: =COUNTIF(BV13:BV200,">"&0) -> 121 | BW11: =COUNTIF(BW13:BW200,">="&Z5) -> 95 | BX11: =COUNTIF(BY13:BY200,">"&0) -> 0 | BZ11: =COUNTIF(BZ13:BZ200,">="&Z5) -> 0
BI12: SUM | BJ12: COUNT | BK12: % | BL12: SUM | BM12: COUNT | BN12: % | BO12: SUM | BP12: COUNT | BQ12: % | BR12: SUM | BS12: COUNT | BT12: % | BU12: SUM | BV12: COUNT | BW12: % | BX12: SUM | BY12: COUNT | BZ12: %
A13: 23N81A6201 | D13: 5 | H13: 4 | J13: 3 | M13: 3 | Q13: 3 | U13: 5 | W13: 3 | X13: 2 | Y13: 5 | AA13: 5 | AC13: 4 | AM13: =SUMIF($D$6:$AJ$6,"IA-1",D13:AJ13)+AK13+AL13 | AP13: =SUMIF($D$6:$AJ$6,"IA-2",D13:AJ13)+AN13+AO13 | BA13: 10 | BB13: 10 | BC13: 10 | BD13: 10 | BE13: 10 | BI13: =SUMIF($D$7:$BG$7,"1",$D13:$BG13) -> 13 | BJ13: =SUMIFS($D$9:$BG$9,$D$7:$BG$7,"1",$D13:$BG13,">"&-1) -> 12.5 | BK13: =ROUNDUP(IF(BJ13,BI13/BJ13%,0),2) -> 104 | BL13: =SUMIF($D$7:$BG$7,"2",$D13:$BG13) -> 27 | BM13: =SUMIFS($D$9:$BG$9,$D$7:$BG$7,"2",$D13:$BG13,">"&-1) -> 27 | BN13: =ROUNDUP(IF(BM13,BL13/BM13%,0),2) -> 100 | BO13: =SUMIF($D$7:$BG$7,"3",$D13:$BG13) -> 24 | BP13: =SUMIFS($D$9:$BG$9,$D$7:$BG$7,"3",$D13:$BG13,">"&-1) -> 25 | BQ13: =ROUNDUP(IF(BP13,BO13/BP13%,0),2) -> 96 | BR13: =SUMIF($D$7:$BG$7,"4",$D13:$BG13) -> 15 | BS13: =SUMIFS($D$9:$BG$9,$D$7:$BG$7,"4",$D13:$BG13,">"&-1) -> 15 | BT13: =ROUNDUP(IF(BS13,BR13/BS13%,0),2) -> 100 | BU13: =SUMIF($D$7:$BG$7,"5",$D13:$BG13) -> 13 | BV13: =SUMIFS($D$9:$BG$9,$D$7:$BG$7,"5",$D13:$BG13,">"&-1) -> 15 | BW13: =ROUNDUP(IF(BV13,BU13/BV13%,0),2) -> 86.67 | BX13: =SUMIF($D$7:$BG$7,"6",$D13:$BG13) -> 0 | BY13: =SUMIFS($D$9:$BG$9,$D$7:$BG$7,"6",$D13:$BG13,">"&-1) -> 0 | BZ13: =ROUNDUP(IF(BY13,BX13/BY13%,0),2) -> 0
A14: 23N81A6202 | D14: 5 | J14: 2 | K14: 0 | L14: 1 | M14: 0 | P14: 1 | Q14: 0 | U14: 5 | W14: 3 | X14: 2 | Y14: 4 | AA14: 5 | BA14: 10 | BB14: 10 | BC14: 10 | BD14: 10 | BE14: 10 | BI14: =SUMIF($D$7:$BG$7,"1",$D14:$BG14) -> 12 | BJ14: =SUMIFS($D$9:$BG$9,$D$7:$BG$7,"1",$D14:$BG14,">"&-1) -> 15 | BK14: =ROUNDUP(IF(BJ14,BI14/BJ14%,0),2) -> 80 | BL14: =SUMIF($D$7:$BG$7,"2",$D14:$BG14) -> 21 | BM14: =SUMIFS($D$9:$BG$9,$D$7:$BG$7,"2",$D14:$BG14,">"&-1) -> 25 | BN14: =ROUNDUP(IF(BM14,BL14/BM14%,0),2) -> 84 | BO14: =SUMIF($D$7:$BG$7,"3",$D14:$BG14) -> 19 | BP14: =SUMIFS($D$9:$BG$9,$D$7:$BG$7,"3",$D14:$BG14,">"&-1) -> 20 | BQ14: =ROUNDUP(IF(BP14,BO14/BP14%,0),2) -> 95 | BR14: =SUMIF($D$7:$BG$7,"4",$D14:$BG14) -> 15 | BS14: =SUMIFS($D$9:$BG$9,$D$7:$BG$7,"4",$D14:$BG14,">"&-1) -> 15 | BT14: =ROUNDUP(IF(BS14,BR14/BS14%,0),2) -> 100 | BU14: =SUMIF($D$7:$BG$7,"5",$D14:$BG14) -> 11 | BV14: =SUMIFS($D$9:$BG$9,$D$7:$BG$7,"5",$D14:$BG14,">"&-1) -> 20 | BW14: =ROUNDUP(IF(BV14,BU14/BV14%,0),2) -> 55 | BX14: =SUMIF($D$7:$BG$7,"6",$D14:$BG14) -> 0 | BY14: =SUMIFS($D$9:$BG$9,$D$7:$BG$7,"6",$D14:$BG14,">"&-1) -> 0 | BZ14: =ROUNDUP(IF(BY14,BX14/BY14%,0),2) -> 0
A15: 23N81A6203 | D15: 5 | F15: 5 | L15: 2 | M15: 3 | P15: 2 | Q15: 3 | U15: 5 | W15: 3 | X15: 2 | Y15: 5 | AA15: 5 | AC15: 4 | AE15: 5 | BA15: 10 | BB15: 10 | BC15: 10 | BD15: 10 | BE15: 10 | BI15: =SUMIF($D$7:$BG$7,"1",$D15:$BG15) -> 10 | BJ15: =SUMIFS($D$9:$BG$9,$D$7:$BG$7,"1",$D15:$BG15,">"&-1) -> 10 | BK15: =ROUNDUP(IF(BJ15,BI15/BJ15%,0),2) -> 100 | BL15: =SUMIF($D$7:$BG$7,"2",$D15:$BG15) -> 25 | BM15: =SUMIFS($D$9:$BG$9,$D$7:$BG$7,"2",$D15:$BG15,">"&-1) -> 25 | BN15: =ROUNDUP(IF(BM15,BL15/BM15%,0),2) -> 100 | BO15: =SUMIF($D$7:$BG$7,"3",$D15:$BG15) -> 34 | BP15: =SUMIFS($D$9:$BG$9,$D$7:$BG$7,"3",$D15:$BG15,">"&-1) -> 35 | BQ15: =ROUNDUP(IF(BP15,BO15/BP15%,0),2) -> 97.15 | BR15: =SUMIF($D$7:$BG$7,"4",$D15:$BG15) -> 15 | BS15: =SUMIFS($D$9:$BG$9,$D$7:$BG$7,"4",$D15:$BG15,">"&-1) -> 15 | BT15: =ROUNDUP(IF(BS15,BR15/BS15%,0),2) -> 100 | BU15: =SUMIF($D$7:$BG$7,"5",$D15:$BG15) -> 15 | BV15: =SUMIFS($D$9:$BG$9,$D$7:$BG$7,"5",$D15:$BG15,">"&-1) -> 20 | BW15: =ROUNDUP(IF(BV15,BU15/BV15%,0),2) -> 75 | BX15: =SUMIF($D$7:$BG$7,"6",$D15:$BG15) -> 0 | BY15: =SUMIFS($D$9:$BG$9,$D$7:$BG$7,"6",$D15:$BG15,">"&-1) -> 0 | BZ15: =ROUNDUP(IF(BY15,BX15/BY15%,0),2) -> 0
A16: 23N81A6204 | D16: 5 | F16: 5 | J16: 2.5 | K16: 2.5 | L16: 2 | M16: 3 | P16: 2 | Q16: 3 | U16: 5 | W16: 3 | X16: 2 | Y16: 5 | AA16: 5 | AC16: 5 | AE16: 5 | BA16: 10 | BB16: 10 | BC16: 10 | BD16: 10 | BE16: 10 | BI16: =SUMIF($D$7:$BG$7,"1",$D16:$BG16) -> 15 | BJ16: =SUMIFS($D$9:$BG$9,$D$7:$BG$7,"1",$D16:$BG16,">"&-1) -> 15 | BK16: =ROUNDUP(IF(BJ16,BI16/BJ16%,0),2) -> 100 | BL16: =SUMIF($D$7:$BG$7,"2",$D16:$BG16) -> 25 | BM16: =SUMIFS($D$9:$BG$9,$D$7:$BG$7,"2",$D16:$BG16,">"&-1) -> 25 | BN16: =ROUNDUP(IF(BM16,BL16/BM16%,0),2) -> 100 | BO16: =SUMIF($D$7:$BG$7,"3",$D16:$BG16) -> 35 | BP16: =SUMIFS($D$9:$BG$9,$D$7:$BG$7,"3",$D16:$BG16,">"&-1) -> 35 | BQ16: =ROUNDUP(IF(BP16,BO16/BP16%,0),2) -> 100 | BR16: =SUMIF($D$7:$BG$7,"4",$D16:$BG16) -> 15 | BS16: =SUMIFS($D$9:$BG$9,$D$7:$BG$7,"4",$D16:$BG16,">"&-1) -> 15 | BT16: =ROUNDUP(IF(BS16,BR16/BS16%,0),2) -> 100 | BU16: =SUMIF($D$7:$BG$7,"5",$D16:$BG16) -> 15 | BV16: =SUMIFS($D$9:$BG$9,$D$7:$BG$7,"5",$D16:$BG16,">"&-1) -> 20 | BW16: =ROUNDUP(IF(BV16,BU16/BV16%,0),2) -> 75 | BX16: =SUMIF($D$7:$BG$7,"6",$D16:$BG16) -> 0 | BY16: =SUMIFS($D$9:$BG$9,$D$7:$BG$7,"6",$D16:$BG16,">"&-1) -> 0 | BZ16: =ROUNDUP(IF(BY16,BX16/BY16%,0),2) -> 0
A17: 23N81A6205 | D17: 5 | F17: 4 | J17: 0 | K17: 1 | L17: 0 | M17: 1 | P17: 0 | Q17: 1 | U17: 5 | W17: 3 | X17: 2 | Y17: 3 | AA17: 5 | AC17: 5 | AE17: 4 | BA17: 9 | BB17: 9 | BC17: 9 | BD17: 9 | BE17: 9 | BI17: =SUMIF($D$7:$BG$7,"1",$D17:$BG17) -> 10 | BJ17: =SUMIFS($D$9:$BG$9,$D$7:$BG$7,"1",$D17:$BG17,">"&-1) -> 15 | BK17: =ROUNDUP(IF(BJ17,BI17/BJ17%,0),2) -> 66.67 | BL17: =SUMIF($D$7:$BG$7,"2",$D17:$BG17) -> 20 | BM17: =SUMIFS($D$9:$BG$9,$D$7:$BG$7,"2",$D17:$BG17,">"&-1) -> 25 | BN17: =ROUNDUP(IF(BM17,BL17/BM17%,0),2) -> 80 | BO17: =SUMIF($D$7:$BG$7,"3",$D17:$BG17) -> 30 | BP17: =SUMIFS($D$9:$BG$9,$D$7:$BG$7,"3",$D17:$BG17,">"&-1) -> 35 | BQ17: =ROUNDUP(IF(BP17,BO17/BP17%,0),2) -> 85.72 | BR17: =SUMIF($D$7:$BG$7,"4",$D17:$BG17) -> 14 | BS17: =SUMIFS($D$9:$BG$9,$D$7:$BG$7,"4",$D17:$BG17,">"&-1) -> 15 | BT17: =ROUNDUP(IF(BS17,BR17/BS17%,0),2) -> 93.34 | BU17: =SUMIF($D$7:$BG$7,"5",$D17:$BG17) -> 10 | BV17: =SUMIFS($D$9:$BG$9,$D$7:$BG$7,"5",$D17:$BG17,">"&-1) -> 20 | BW17: =ROUNDUP(IF(BV17,BU17/BV17%,0),2) -> 50 | BX17: =SUMIF($D$7:$BG$7,"6",$D17:$BG17) -> 0 | BY17: =SUMIFS($D$9:$BG$9,$D$7:$BG$7,"6",$D17:$BG17,">"&-1) -> 0 | BZ17: =ROUNDUP(IF(BY17,BX17/BY17%,0),2) -> 0
A18: 23N81A6206 | D18: 5 | F18: 5 | J18: 2 | K18: 2 | L18: 1 | M18: 0 | P18: 1 | Q18: 0 | U18: 5 | W18: 3 | X18: 2 | Y18: 2 | AA18: 4 | AC18: 3 | BA18: 10 | BB18: 10 | BC18: 10 | BD18: 10 | BE18: 10 | BI18: =SUMIF($D$7:$BG$7,"1",$D18:$BG18) -> 14 | BJ18: =SUMIFS($D$9:$BG$9,$D$7:$BG$7,"1",$D18:$BG18,">"&-1) -> 15 | BK18: =ROUNDUP(IF(BJ18,BI18/BJ18%,0),2) -> 93.34 | BL18: =SUMIF($D$7:$BG$7,"2",$D18:$BG18) -> 21 | BM18: =SUMIFS($D$9:$BG$9,$D$7:$BG$7,"2",$D18:$BG18,">"&-1) -> 25 | BN18: =ROUNDUP(IF(BM18,BL18/BM18%,0),2) -> 84 | BO18: =SUMIF($D$7:$BG$7,"3",$D18:$BG18) -> 25 | BP18: =SUMIFS($D$9:$BG$9,$D$7:$BG$7,"3",$D18:$BG18,">"&-1) -> 30 | BQ18: =ROUNDUP(IF(BP18,BO18/BP18%,0),2) -> 83.34 | BR18: =SUMIF($D$7:$BG$7,"4",$D18:$BG18) -> 14 | BS18: =SUMIFS($D$9:$BG$9,$D$7:$BG$7,"4",$D18:$BG18,">"&-1) -> 15 | BT18: =ROUNDUP(IF(BS18,BR18/BS18%,0),2) -> 93.34 | BU18: =SUMIF($D$7:$BG$7,"5",$D18:$BG18) -> 11 | BV18: =SUMIFS($D$9:$BG$9,$D$7:$BG$7,"5",$D18:$BG18,">"&-1) -> 20 | BW18: =ROUNDUP(IF(BV18,BU18/BV18%,0),2) -> 55 | BX18: =SUMIF($D$7:$BG$7,"6",$D18:$BG18) -> 0 | BY18: =SUMIFS($D$9:$BG$9,$D$7:$BG$7,"6",$D18:$BG18,">"&-1) -> 0 | BZ18: =ROUNDUP(IF(BY18,BX18/BY18%,0),2) -> 0
A19: 23N81A6207 | D19: 5 | H19: 2 | J19: 1 | K19: 2 | L19: 0 | M19: 2 | P19: 0 | Q19: 2 | U19: 0 | W19: 3 | X19: 2 | AA19: 3 | AC19: 4 | BA19: 10 | BB19: 10 | BC19: 10 | BD19: 10 | BE19: 10 | BI19: =SUMIF($D$7:$BG$7,"1",$D19:$BG19) -> 13 | BJ19: =SUMIFS($D$9:$BG$9,$D$7:$BG$7,"1",$D19:$BG19,">"&-1) -> 15 | BK19: =ROUNDUP(IF(BJ19,BI19/BJ19%,0),2) -> 86.67 | BL19: =SUMIF($D$7:$BG$7,"2",$D19:$BG19) -> 24 | BM19: =SUMIFS($D$9:$BG$9,$D$7:$BG$7,"2",$D19:$BG19,">"&-1) -> 30 | BN19: =ROUNDUP(IF(BM19,BL19/BM19%,0),2) -> 80 | BO19: =SUMIF($D$7:$BG$7,"3",$D19:$BG19) -> 14 | BP19: =SUMIFS($D$9:$BG$9,$D$7:$BG$7,"3",$D19:$BG19,">"&-1) -> 20 | BQ19: =ROUNDUP(IF(BP19,BO19/BP19%,0),2) -> 70 | BR19: =SUMIF($D$7:$BG$7,"4",$D19:$BG19) -> 13 | BS19: =SUMIFS($D$9:$BG$9,$D$7:$BG$7,"4",$D19:$BG19,">"&-1) -> 15 | BT19: =ROUNDUP(IF(BS19,BR19/BS19%,0),2) -> 86.67 | BU19: =SUMIF($D$7:$BG$7,"5",$D19:$BG19) -> 12 | BV19: =SUMIFS($D$9:$BG$9,$D$7:$BG$7,"5",$D19:$BG19,">"&-1) -> 20 | BW19: =ROUNDUP(IF(BV19,BU19/BV19%,0),2) -> 60 | BX19: =SUMIF($D$7:$BG$7,"6",$D19:$BG19) -> 0 | BY19: =SUMIFS($D$9:$BG$9,$D$7:$BG$7,"6",$D19:$BG19,">"&-1) -> 0 | BZ19: =ROUNDUP(IF(BY19,BX19/BY19%,0),2) -> 0
A20: 23N81A6208 | D20: 0 | E20: 0 | F20: 0 | G20: 0 | H20: 0 | I20: 0 | J20: 0 | K20: 0 | L20: 0 | M20: 0 | N20: 0 | O20: 0 | P20: 0 | Q20: 0 | U20: 5 | W20: 3 | X20: 2 | BA20: 7.5 | BB20: 7.5 | BC20: 7.5 | BD20: 7.5 | BE20: 7.5 | BI20: =SUMIF($D$7:$BG$7,"1",$D20:$BG20) -> 7.5 | BJ20: =SUMIFS($D$9:$BG$9,$D$7:$BG$7,"1",$D20:$BG20,">"&-1) -> 15 | BK20: =ROUNDUP(IF(BJ20,BI20/BJ20%,0),2) -> 50 | BL20: =SUMIF($D$7:$BG$7,"2",$D20:$BG20) -> 12.5 | BM20: =SUMIFS($D$9:$BG$9,$D$7:$BG$7,"2",$D20:$BG20,">"&-1) -> 30 | BN20: =ROUNDUP(IF(BM20,BL20/BM20%,0),2) -> 41.67 | BO20: =SUMIF($D$7:$BG$7,"3",$D20:$BG20) -> 12.5 | BP20: =SUMIFS($D$9:$BG$9,$D$7:$BG$7,"3",$D20:$BG20,">"&-1) -> 25 | BQ20: =ROUNDUP(IF(BP20,BO20/BP20%,0),2) -> 50 | BR20: =SUMIF($D$7:$BG$7,"4",$D20:$BG20) -> 7.5 | BS20: =SUMIFS($D$9:$BG$9,$D$7:$BG$7,"4",$D20:$BG20,">"&-1) -> 10 | BT20: =ROUNDUP(IF(BS20,BR20/BS20%,0),2) -> 75 | BU20: =SUMIF($D$7:$BG$7,"5",$D20:$BG20) -> 7.5 | BV20: =SUMIFS($D$9:$BG$9,$D$7:$BG$7,"5",$D20:$BG20,">"&-1) -> 20 | BW20: =ROUNDUP(IF(BV20,BU20/BV20%,0),2) -> 37.5 | BX20: =SUMIF($D$7:$BG$7,"6",$D20:$BG20) -> 0 | BY20: =SUMIFS($D$9:$BG$9,$D$7:$BG$7,"6",$D20:$BG20,">"&-1) -> 0 | BZ20: =ROUNDUP(IF(BY20,BX20/BY20%,0),2) -> 0
A21: 23N81A6209 | D21: 1 | U21: 1 | W21: 2 | BA21: 10 | BB21: 10 | BC21: 10 | BD21: 10 | BE21: 10 | BI21: =SUMIF($D$7:$BG$7,"1",$D21:$BG21) -> 10 | BJ21: =SUMIFS($D$9:$BG$9,$D$7:$BG$7,"1",$D21:$BG21,">"&-1) -> 10 | BK21: =ROUNDUP(IF(BJ21,BI21/BJ21%,0),2) -> 100 | BL21: =SUMIF($D$7:$BG$7,"2",$D21:$BG21) -> 13 | BM21: =SUMIFS($D$9:$BG$9,$D$7:$BG$7,"2",$D21:$BG21,">"&-1) -> 18 | BN21: =ROUNDUP(IF(BM21,BL21/BM21%,0),2) -> 72.23 | BO21: =SUMIF($D$7:$BG$7,"3",$D21:$BG21) -> 11 | BP21: =SUMIFS($D$9:$BG$9,$D$7:$BG$7,"3",$D21:$BG21,">"&-1) -> 15 | BQ21: =ROUNDUP(IF(BP21,BO21/BP21%,0),2) -> 73.34 | BR21: =SUMIF($D$7:$BG$7,"4",$D21:$BG21) -> 10 | BS21: =SUMIFS($D$9:$BG$9,$D$7:$BG$7,"4",$D21:$BG21,">"&-1) -> 10 | BT21: =ROUNDUP(IF(BS21,BR21/BS21%,0),2) -> 100 | BU21: =SUMIF($D$7:$BG$7,"5",$D21:$BG21) -> 10 | BV21: =SUMIFS($D$9:$BG$9,$D$7:$BG$7,"5",$D21:$BG21,">"&-1) -> 10 | BW21: =ROUNDUP(IF(BV21,BU21/BV21%,0),2) -> 100 | BX21: =SUMIF($D$7:$BG$7,"6",$D21:$BG21) -> 0 | BY21: =SUMIFS($D$9:$BG$9,$D$7:$BG$7,"6",$D21:$BG21,">"&-1) -> 0 | BZ21: =ROUNDUP(IF(BY21,BX21/BY21%,0),2) -> 0
A22: 23N81A6210 | D22: 5 | F22: 5 | H22: 2 | J22: 2 | K22: 2 | L22: 1 | M22: 3 | P22: 1 | Q22: 3 | U22: 5 | W22: 3 | X22: 2 | Y22: 5 | AA22: 5 | AC22: 4 | AE22: 3 | BA22: 10 | BB22: 10 | BC22: 10 | BD22: 10 | BE22: 10 | BI22: =SUMIF($D$7:$BG$7,"1",$D22:$BG22) -> 14 | BJ22: =SUMIFS($D$9:$BG$9,$D$7:$BG$7,"1",$D22:$BG22,">"&-1) -> 15 | BK22: =ROUNDUP(IF(BJ22,BI22/BJ22%,0),2) -> 93.34 | BL22: =SUMIF($D$7:$BG$7,"2",$D22:$BG22) -> 26 | BM22: =SUMIFS($D$9:$BG$9,$D$7:$BG$7,"2",$D22:$BG22,">"&-1) -> 30 | BN22: =ROUNDUP(IF(BM22,BL22/BM22%,0),2) -> 86.67 | BO22: =SUMIF($D$7:$BG$7,"3",$D22:$BG22) -> 32 | BP22: =SUMIFS($D$9:$BG$9,$D$7:$BG$7,"3",$D22:$BG22,">"&-1) -> 35 | BQ22: =ROUNDUP(IF(BP22,BO22/BP22%,0),2) -> 91.43 | BR22: =SUMIF($D$7:$BG$7,"4",$D22:$BG22) -> 15 | BS22: =SUMIFS($D$9:$BG$9,$D$7:$BG$7,"4",$D22:$BG22,">"&-1) -> 15 | BT22: =ROUNDUP(IF(BS22,BR22/BS22%,0),2) -> 100 | BU22: =SUMIF($D$7:$BG$7,"5",$D22:$BG22) -> 14 | BV22: =SUMIFS($D$9:$BG$9,$D$7:$BG$7,"5",$D22:$BG22,">"&-1) -> 20 | BW22: =ROUNDUP(IF(BV22,BU22/BV22%,0),2) -> 70 | BX22: =SUMIF($D$7:$BG$7,"6",$D22:$BG22) -> 0 | BY22: =SUMIFS($D$9:$BG$9,$D$7:$BG$7,"6",$D22:$BG22,">"&-1) -> 0 | BZ22: =ROUNDUP(IF(BY22,BX22/BY22%,0),2) -> 0
A23: 23N81A6211 | D23: 5 | J23: 0 | K23: 2 | L23: 0 | M23: 3 | P23: 0 | Q23: 3 | U23: 5 | W23: 3 | X23: 2 | Y23: 2 | AA23: 1 | BA23: 10 | BB23: 10 | BC23: 10 | BD23: 10 | BE23: 10 | BI23: =SUMIF($D$7:$BG$7,"1",$D23:$BG23) -> 12 | BJ23: =SUMIFS($D$9:$BG$9,$D$7:$BG$7,"1",$D23:$BG23,">"&-1) -> 15 | BK23: =ROUNDUP(IF(BJ23,BI23/BJ23%,0),2) -> 80 | BL23: =SUMIF($D$7:$BG$7,"2",$D23:$BG23) -> 23 | BM23: =SUMIFS($D$9:$BG$9,$D$7:$BG$7,"2",$D23:$BG23,">"&-1) -> 25 | BN23: =ROUNDUP(IF(BM23,BL23/BM23%,0),2) -> 92 | BO23: =SUMIF($D$7:$BG$7,"3",$D23:$BG23) -> 17 | BP23: =SUMIFS($D$9:$BG$9,$D$7:$BG$7,"3",$D23:$BG23,">"&-1) -> 20 | BQ23: =ROUNDUP(IF(BP23,BO23/BP23%,0),2) -> 85 | BR23: =SUMIF($D$7:$BG$7,"4",$D23:$BG23) -> 11 | BS23: =SUMIFS($D$9:$BG$9,$D$7:$BG$7,"4",$D23:$BG23,">"&-1) -> 15 | BT23: =ROUNDUP(IF(BS23,BR23/BS23%,0),2) -> 73.34 | BU23: =SUMIF($D$7:$BG$7,"5",$D23:$BG23) -> 13 | BV23: =SUMIFS($D$9:$BG$9,$D$7:$BG$7,"5",$D23:$BG23,">"&-1) -> 20 | BW23: =ROUNDUP(IF(BV23,BU23/BV23%,0),2) -> 65 | BX23: =SUMIF($D$7:$BG$7,"6",$D23:$BG23) -> 0 | BY23: =SUMIFS($D$9:$BG$9,$D$7:$BG$7,"6",$D23:$BG23,">"&-1) -> 0 | BZ23: =ROUNDUP(IF(BY23,BX23/BY23%,0),2) -> 0
A24: 23N81A6212 | D24: 4 | J24: 2.5 | K24: 2.5 | U24: 4 | W24: 3 | X24: 2 | Y24: 5 | AC24: 3 | BA24: 10 | BB24: 10 | BC24: 10 | BD24: 10 | BE24: 10 | BI24: =SUMIF($D$7:$BG$7,"1",$D24:$BG24) -> 15 | BJ24: =SUMIFS($D$9:$BG$9,$D$7:$BG$7,"1",$D24:$BG24,">"&-1) -> 15 | BK24: =ROUNDUP(IF(BJ24,BI24/BJ24%,0),2) -> 100 | BL24: =SUMIF($D$7:$BG$7,"2",$D24:$BG24) -> 19 | BM24: =SUMIFS($D$9:$BG$9,$D$7:$BG$7,"2",$D24:$BG24,">"&-1) -> 20 | BN24: =ROUNDUP(IF(BM24,BL24/BM24%,0),2) -> 95 | BO24: =SUMIF($D$7:$BG$7,"3",$D24:$BG24) -> 22 | BP24: =SUMIFS($D$9:$BG$9,$D$7:$BG$7,"3",$D24:$BG24,">"&-1) -> 25 | BQ24: =ROUNDUP(IF(BP24,BO24/BP24%,0),2) -> 88 | BR24: =SUMIF($D$7:$BG$7,"4",$D24:$BG24) -> 10 | BS24: =SUMIFS($D$9:$BG$9,$D$7:$BG$7,"4",$D24:$BG24,">"&-1) -> 10 | BT24: =ROUNDUP(IF(BS24,BR24/BS24%,0),2) -> 100 | BU24: =SUMIF($D$7:$BG$7,"5",$D24:$BG24) -> 10 | BV24: =SUMIFS($D$9:$BG$9,$D$7:$BG$7,"5",$D24:$BG24,">"&-1) -> 10 | BW24: =ROUNDUP(IF(BV24,BU24/BV24%,0),2) -> 100 | BX24: =SUMIF($D$7:$BG$7,"6",$D24:$BG24) -> 0 | BY24: =SUMIFS($D$9:$BG$9,$D$7:$BG$7,"6",$D24:$BG24,">"&-1) -> 0 | BZ24: =ROUNDUP(IF(BY24,BX24/BY24%,0),2) -> 0
A25: 23N81A6213 | D25: 5 | H25: 1 | I25: 0 | J25: 0 | K25: 2 | U25: 5 | W25: 3 | X25: 2 | Y25: 2 | AC25: 2 | BA25: 10 | BB25: 10 | BC25: 10 | BD25: 10 | BE25: 10 | BI25: =SUMIF($D$7:$BG$7,"1",$D25:$BG25) -> 12 | BJ25: =SUMIFS($D$9:$BG$9,$D$7:$BG$7,"1",$D25:$BG25,">"&-1) -> 15 | BK25: =ROUNDUP(IF(BJ25,BI25/BJ25%,0),2) -> 80 | BL25: =SUMIF($D$7:$BG$7,"2",$D25:$BG25) -> 21 | BM25: =SUMIFS($D$9:$BG$9,$D$7:$BG$7,"2",$D25:$BG25,">"&-1) -> 25 | BN25: =ROUNDUP(IF(BM25,BL25/BM25%,0),2) -> 84 | BO25: =SUMIF($D$7:$BG$7,"3",$D25:$BG25) -> 19 | BP25: =SUMIFS($D$9:$BG$9,$D$7:$BG$7,"3",$D25:$BG25,">"&-1) -> 25 | BQ25: =ROUNDUP(IF(BP25,BO25/BP25%,0),2) -> 76 | BR25: =SUMIF($D$7:$BG$7,"4",$D25:$BG25) -> 10 | BS25: =SUMIFS($D$9:$BG$9,$D$7:$BG$7,"4",$D25:$BG25,">"&-1) -> 10 | BT25: =ROUNDUP(IF(BS25,BR25/BS25%,0),2) -> 100 | BU25: =SUMIF($D$7:$BG$7,"5",$D25:$BG25) -> 10 | BV25: =SUMIFS($D$9:$BG$9,$D$7:$BG$7,"5",$D25:$BG25,">"&-1) -> 10 | BW25: =ROUNDUP(IF(BV25,BU25/BV25%,0),2) -> 100 | BX25: =SUMIF($D$7:$BG$7,"6",$D25:$BG25) -> 0 | BY25: =SUMIFS($D$9:$BG$9,$D$7:$BG$7,"6",$D25:$BG25,">"&-1) -> 0 | BZ25: =ROUNDUP(IF(BY25,BX25/BY25%,0),2) -> 0
A26: 23N81A6214 | D26: 2 | U26: 5 | W26: 3 | X26: 2 | BA26: 10 | BB26: 10 | BC26: 10 | BD26: 10 | BE26: 10 | BI26: =SUMIF($D$7:$BG$7,"1",$D26:$BG26) -> 10 | BJ26: =SUMIFS($D$9:$BG$9,$D$7:$BG$7,"1",$D26:$BG26,">"&-1) -> 10 | BK26: =ROUNDUP(IF(BJ26,BI26/BJ26%,0),2) -> 100 | BL26: =SUMIF($D$7:$BG$7,"2",$D26:$BG26) -> 17 | BM26: =SUMIFS($D$9:$BG$9,$D$7:$BG$7,"2",$D26:$BG26,">"&-1) -> 20 | BN26: =ROUNDUP(IF(BM26,BL26/BM26%,0),2) -> 85 | BO26: =SUMIF($D$7:$BG$7,"3",$D26:$BG26) -> 15 | BP26: =SUMIFS($D$9:$BG$9,$D$7:$BG$7,"3",$D26:$BG26,">"&-1) -> 15 | BQ26: =ROUNDUP(IF(BP26,BO26/BP26%,0),2) -> 100 | BR26: =SUMIF($D$7:$BG$7,"4",$D26:$BG26) -> 10 | BS26: =SUMIFS($D$9:$BG$9,$D$7:$BG$7,"4",$D26:$BG26,">"&-1) -> 10 | BT26: =ROUNDUP(IF(BS26,BR26/BS26%,0),2) -> 100 | BU26: =SUMIF($D$7:$BG$7,"5",$D26:$BG26) -> 10 | BV26: =SUMIFS($D$9:$BG$9,$D$7:$BG$7,"5",$D26:$BG26,">"&-1) -> 10 | BW26: =ROUNDUP(IF(BV26,BU26/BV26%,0),2) -> 100 | BX26: =SUMIF($D$7:$BG$7,"6",$D26:$BG26) -> 0 | BY26: =SUMIFS($D$9:$BG$9,$D$7:$BG$7,"6",$D26:$BG26,">"&-1) -> 0 | BZ26: =ROUNDUP(IF(BY26,BX26/BY26%,0),2) -> 0
A27: 23N81A6216 | D27: 2 | M27: 2 | Q27: 2 | U27: 5 | W27: 3 | X27: 2 | BA27: 10 | BB27: 10 | BC27: 10 | BD27: 10 | BE27: 10 | BI27: =SUMIF($D$7:$BG$7,"1",$D27:$BG27) -> 10 | BJ27: =SUMIFS($D$9:$BG$9,$D$7:$BG$7,"1",$D27:$BG27,">"&-1) -> 10 | BK27: =ROUNDUP(IF(BJ27,BI27/BJ27%,0),2) -> 100 | BL27: =SUMIF($D$7:$BG$7,"2",$D27:$BG27) -> 19 | BM27: =SUMIFS($D$9:$BG$9,$D$7:$BG$7,"2",$D27:$BG27,">"&-1) -> 22 | BN27: =ROUNDUP(IF(BM27,BL27/BM27%,0),2) -> 86.37 | BO27: =SUMIF($D$7:$BG$7,"3",$D27:$BG27) -> 15 | BP27: =SUMIFS($D$9:$BG$9,$D$7:$BG$7,"3",$D27:$BG27,">"&-1) -> 15 | BQ27: =ROUNDUP(IF(BP27,BO27/BP27%,0),2) -> 100 | BR27: =SUMIF($D$7:$BG$7,"4",$D27:$BG27) -> 10 | BS27: =SUMIFS($D$9:$BG$9,$D$7:$BG$7,"4",$D27:$BG27,">"&-1) -> 10 | BT27: =ROUNDUP(IF(BS27,BR27/BS27%,0),2) -> 100 | BU27: =SUMIF($D$7:$BG$7,"5",$D27:$BG27) -> 12 | BV27: =SUMIFS($D$9:$BG$9,$D$7:$BG$7,"5",$D27:$BG27,">"&-1) -> 15 | BW27: =ROUNDUP(IF(BV27,BU27/BV27%,0),2) -> 80 | BX27: =SUMIF($D$7:$BG$7,"6",$D27:$BG27) -> 0 | BY27: =SUMIFS($D$9:$BG$9,$D$7:$BG$7,"6",$D27:$BG27,">"&-1) -> 0 | BZ27: =ROUNDUP(IF(BY27,BX27/BY27%,0),2) -> 0
A28: 23N81A6217 | D28: 5 | J28: 2.5 | K28: 2.5 | L28: 2 | M28: 2 | P28: 2 | Q28: 2 | U28: 5 | W28: 3 | X28: 2 | Y28: 5 | AA28: 5 | AC28: 3 | BA28: 10 | BB28: 10 | BC28: 10 | BD28: 10 | BE28: 10 | BI28: =SUMIF($D$7:$BG$7,"1",$D28:$BG28) -> 15 | BJ28: =SUMIFS($D$9:$BG$9,$D$7:$BG$7,"1",$D28:$BG28,">"&-1) -> 15 | BK28: =ROUNDUP(IF(BJ28,BI28/BJ28%,0),2) -> 100 | BL28: =SUMIF($D$7:$BG$7,"2",$D28:$BG28) -> 24 | BM28: =SUMIFS($D$9:$BG$9,$D$7:$BG$7,"2",$D28:$BG28,">"&-1) -> 25 | BN28: =ROUNDUP(IF(BM28,BL28/BM28%,0),2) -> 96 | BO28: =SUMIF($D$7:$BG$7,"3",$D28:$BG28) -> 23 | BP28: =SUMIFS($D$9:$BG$9,$D$7:$BG$7,"3",$D28:$BG28,">"&-1) -> 25 | BQ28: =ROUNDUP(IF(BP28,BO28/BP28%,0),2) -> 92 | BR28: =SUMIF($D$7:$BG$7,"4",$D28:$BG28) -> 15 | BS28: =SUMIFS($D$9:$BG$9,$D$7:$BG$7,"4",$D28:$BG28,">"&-1) -> 15 | BT28: =ROUNDUP(IF(BS28,BR28/BS28%,0),2) -> 100 | BU28: =SUMIF($D$7:$BG$7,"5",$D28:$BG28) -> 14 | BV28: =SUMIFS($D$9:$BG$9,$D$7:$BG$7,"5",$D28:$BG28,">"&-1) -> 20 | BW28: =ROUNDUP(IF(BV28,BU28/BV28%,0),2) -> 70 | BX28: =SUMIF($D$7:$BG$7,"6",$D28:$BG28) -> 0 | BY28: =SUMIFS($D$9:$BG$9,$D$7:$BG$7,"6",$D28:$BG28,">"&-1) -> 0 | BZ28: =ROUNDUP(IF(BY28,BX28/BY28%,0),2) -> 0
A29: 23N81A6218 | D29: 4 | F29: 4 | J29: 2 | K29: 2 | L29: 1 | M29: 3 | P29: 1 | Q29: 3 | U29: 5 | W29: 3 | X29: 2 | Y29: 5 | AA29: 5 | BA29: 10 | BB29: 10 | BC29: 10 | BD29: 10 | BE29: 10 | BI29: =SUMIF($D$7:$BG$7,"1",$D29:$BG29) -> 14 | BJ29: =SUMIFS($D$9:$BG$9,$D$7:$BG$7,"1",$D29:$BG29,">"&-1) -> 15 | BK29: =ROUNDUP(IF(BJ29,BI29/BJ29%,0),2) -> 93.34 | BL29: =SUMIF($D$7:$BG$7,"2",$D29:$BG29) -> 23 | BM29: =SUMIFS($D$9:$BG$9,$D$7:$BG$7,"2",$D29:$BG29,">"&-1) -> 25 | BN29: =ROUNDUP(IF(BM29,BL29/BM29%,0),2) -> 92 | BO29: =SUMIF($D$7:$BG$7,"3",$D29:$BG29) -> 24 | BP29: =SUMIFS($D$9:$BG$9,$D$7:$BG$7,"3",$D29:$BG29,">"&-1) -> 25 | BQ29: =ROUNDUP(IF(BP29,BO29/BP29%,0),2) -> 96 | BR29: =SUMIF($D$7:$BG$7,"4",$D29:$BG29) -> 15 | BS29: =SUMIFS($D$9:$BG$9,$D$7:$BG$7,"4",$D29:$BG29,">"&-1) -> 15 | BT29: =ROUNDUP(IF(BS29,BR29/BS29%,0),2) -> 100 | BU29: =SUMIF($D$7:$BG$7,"5",$D29:$BG29) -> 14 | BV29: =SUMIFS($D$9:$BG$9,$D$7:$BG$7,"5",$D29:$BG29,">"&-1) -> 20 | BW29: =ROUNDUP(IF(BV29,BU29/BV29%,0),2) -> 70 | BX29: =SUMIF($D$7:$BG$7,"6",$D29:$BG29) -> 0 | BY29: =SUMIFS($D$9:$BG$9,$D$7:$BG$7,"6",$D29:$BG29,">"&-1) -> 0 | BZ29: =ROUNDUP(IF(BY29,BX29/BY29%,0),2) -> 0
A30: 23N81A6219 | D30: 4 | H30: 3 | J30: 2 | K30: 0 | U30: 5 | Y30: 4 | AA30: 5 | AC30: 5 | AE30: 5 | BA30: 10 | BB30: 10 | BC30: 10 | BD30: 10 | BE30: 10 | BI30: =SUMIF($D$7:$BG$7,"1",$D30:$BG30) -> 12 | BJ30: =SUMIFS($D$9:$BG$9,$D$7:$BG$7,"1",$D30:$BG30,">"&-1) -> 15 | BK30: =ROUNDUP(IF(BJ30,BI30/BJ30%,0),2) -> 80 | BL30: =SUMIF($D$7:$BG$7,"2",$D30:$BG30) -> 17 | BM30: =SUMIFS($D$9:$BG$9,$D$7:$BG$7,"2",$D30:$BG30,">"&-1) -> 20 | BN30: =ROUNDUP(IF(BM30,BL30/BM30%,0),2) -> 85 | BO30: =SUMIF($D$7:$BG$7,"3",$D30:$BG30) -> 29 | BP30: =SUMIFS($D$9:$BG$9,$D$7:$BG$7,"3",$D30:$BG30,">"&-1) -> 30 | BQ30: =ROUNDUP(IF(BP30,BO30/BP30%,0),2) -> 96.67 | BR30: =SUMIF($D$7:$BG$7,"4",$D30:$BG30) -> 15 | BS30: =SUMIFS($D$9:$BG$9,$D$7:$BG$7,"4",$D30:$BG30,">"&-1) -> 15 | BT30: =ROUNDUP(IF(BS30,BR30/BS30%,0),2) -> 100 | BU30: =SUMIF($D$7:$BG$7,"5",$D30:$BG30) -> 10 | BV30: =SUMIFS($D$9:$BG$9,$D$7:$BG$7,"5",$D30:$BG30,">"&-1) -> 10 | BW30: =ROUNDUP(IF(BV30,BU30/BV30%,0),2) -> 100 | BX30: =SUMIF($D$7:$BG$7,"6",$D30:$BG30) -> 0 | BY30: =SUMIFS($D$9:$BG$9,$D$7:$BG$7,"6",$D30:$BG30,">"&-1) -> 0 | BZ30: =ROUNDUP(IF(BY30,BX30/BY30%,0),2) -> 0
A31: 23N81A6220 | D31: 5 | H31: 5 | J31: 2.5 | K31: 2.5 | L31: 2 | M31: 3 | P31: 2 | Q31: 3 | U31: 3 | W31: 3 | X31: 2 | Y31: 5 | AA31: 5 | AC31: 4 | BA31: 10 | BB31: 10 | BC31: 10 | BD31: 10 | BE31: 10 | BI31: =SUMIF($D$7:$BG$7,"1",$D31:$BG31) -> 15 | BJ31: =SUMIFS($D$9:$BG$9,$D$7:$BG$7,"1",$D31:$BG31,">"&-1) -> 15 | BK31: =ROUNDUP(IF(BJ31,BI31/BJ31%,0),2) -> 100 | BL31: =SUMIF($D$7:$BG$7,"2",$D31:$BG31) -> 30 | BM31: =SUMIFS($D$9:$BG$9,$D$7:$BG$7,"2",$D31:$BG31,">"&-1) -> 30 | BN31: =ROUNDUP(IF(BM31,BL31/BM31%,0),2) -> 100 | BO31: =SUMIF($D$7:$BG$7,"3",$D31:$BG31) -> 22 | BP31: =SUMIFS($D$9:$BG$9,$D$7:$BG$7,"3",$D31:$BG31,">"&-1) -> 25 | BQ31: =ROUNDUP(IF(BP31,BO31/BP31%,0),2) -> 88 | BR31: =SUMIF($D$7:$BG$7,"4",$D31:$BG31) -> 15 | BS31: =SUMIFS($D$9:$BG$9,$D$7:$BG$7,"4",$D31:$BG31,">"&-1) -> 15 | BT31: =ROUNDUP(IF(BS31,BR31/BS31%,0),2) -> 100 | BU31: =SUMIF($D$7:$BG$7,"5",$D31:$BG31) -> 15 | BV31: =SUMIFS($D$9:$BG$9,$D$7:$BG$7,"5",$D31:$BG31,">"&-1) -> 20 | BW31: =ROUNDUP(IF(BV31,BU31/BV31%,0),2) -> 75 | BX31: =SUMIF($D$7:$BG$7,"6",$D31:$BG31) -> 0 | BY31: =SUMIFS($D$9:$BG$9,$D$7:$BG$7,"6",$D31:$BG31,">"&-1) -> 0 | BZ31: =ROUNDUP(IF(BY31,BX31/BY31%,0),2) -> 0
A32: 23N81A6221 | D32: 5 | H32: 4 | J32: 2.5 | K32: 2.5 | L32: 2 | M32: 5 | P32: 2 | Q32: 5 | U32: 5 | W32: 3 | X32: 2 | Y32: 5 | AA32: 5 | AC32: 5 | AE32: 4 | BA32: 10 | BB32: 10 | BC32: 10 | BD32: 10 | BE32: 10 | BI32: =SUMIF($D$7:$BG$7,"1",$D32:$BG32) -> 15 | BJ32: =SUMIFS($D$9:$BG$9,$D$7:$BG$7,"1",$D32:$BG32,">"&-1) -> 15 | BK32: =ROUNDUP(IF(BJ32,BI32/BJ32%,0),2) -> 100 | BL32: =SUMIF($D$7:$BG$7,"2",$D32:$BG32) -> 31 | BM32: =SUMIFS($D$9:$BG$9,$D$7:$BG$7,"2",$D32:$BG32,">"&-1) -> 30 | BN32: =ROUNDUP(IF(BM32,BL32/BM32%,0),2) -> 103.34 | BO32: =SUMIF($D$7:$BG$7,"3",$D32:$BG32) -> 29 | BP32: =SUMIFS($D$9:$BG$9,$D$7:$BG$7,"3",$D32:$BG32,">"&-1) -> 30 | BQ32: =ROUNDUP(IF(BP32,BO32/BP32%,0),2) -> 96.67 | BR32: =SUMIF($D$7:$BG$7,"4",$D32:$BG32) -> 15 | BS32: =SUMIFS($D$9:$BG$9,$D$7:$BG$7,"4",$D32:$BG32,">"&-1) -> 15 | BT32: =ROUNDUP(IF(BS32,BR32/BS32%,0),2) -> 100 | BU32: =SUMIF($D$7:$BG$7,"5",$D32:$BG32) -> 17 | BV32: =SUMIFS($D$9:$BG$9,$D$7:$BG$7,"5",$D32:$BG32,">"&-1) -> 20 | BW32: =ROUNDUP(IF(BV32,BU32/BV32%,0),2) -> 85 | BX32: =SUMIF($D$7:$BG$7,"6",$D32:$BG32) -> 0 | BY32: =SUMIFS($D$9:$BG$9,$D$7:$BG$7,"6",$D32:$BG32,">"&-1) -> 0 | BZ32: =ROUNDUP(IF(BY32,BX32/BY32%,0),2) -> 0
A33: 23N81A6222 | D33: 5 | F33: 5 | H33: 5 | L33: 2 | P33: 2 | U33: 5 | W33: 3 | X33: 2 | AC33: 5 | AE33: 4 | BA33: 10 | BB33: 10 | BC33: 10 | BD33: 10 | BE33: 10 | BI33: =SUMIF($D$7:$BG$7,"1",$D33:$BG33) -> 10 | BJ33: =SUMIFS($D$9:$BG$9,$D$7:$BG$7,"1",$D33:$BG33,">"&-1) -> 10 | BK33: =ROUNDUP(IF(BJ33,BI33/BJ33%,0),2) -> 100 | BL33: =SUMIF($D$7:$BG$7,"2",$D33:$BG33) -> 27 | BM33: =SUMIFS($D$9:$BG$9,$D$7:$BG$7,"2",$D33:$BG33,">"&-1) -> 28 | BN33: =ROUNDUP(IF(BM33,BL33/BM33%,0),2) -> 96.43 | BO33: =SUMIF($D$7:$BG$7,"3",$D33:$BG33) -> 29 | BP33: =SUMIFS($D$9:$BG$9,$D$7:$BG$7,"3",$D33:$BG33,">"&-1) -> 30 | BQ33: =ROUNDUP(IF(BP33,BO33/BP33%,0),2) -> 96.67 | BR33: =SUMIF($D$7:$BG$7,"4",$D33:$BG33) -> 10 | BS33: =SUMIFS($D$9:$BG$9,$D$7:$BG$7,"4",$D33:$BG33,">"&-1) -> 10 | BT33: =ROUNDUP(IF(BS33,BR33/BS33%,0),2) -> 100 | BU33: =SUMIF($D$7:$BG$7,"5",$D33:$BG33) -> 12 | BV33: =SUMIFS($D$9:$BG$9,$D$7:$BG$7,"5",$D33:$BG33,">"&-1) -> 15 | BW33: =ROUNDUP(IF(BV33,BU33/BV33%,0),2) -> 80 | BX33: =SUMIF($D$7:$BG$7,"6",$D33:$BG33) -> 0 | BY33: =SUMIFS($D$9:$BG$9,$D$7:$BG$7,"6",$D33:$BG33,">"&-1) -> 0 | BZ33: =ROUNDUP(IF(BY33,BX33/BY33%,0),2) -> 0
A34: 23N81A6223 | D34: 5 | J34: 2.5 | K34: 2.5 | L34: 1 | M34: 3 | P34: 1 | Q34: 3 | U34: 5 | W34: 3 | X34: 2 | Y34: 5 | AA34: 5 | BA34: 10 | BB34: 10 | BC34: 10 | BD34: 10 | BE34: 10 | BI34: =SUMIF($D$7:$BG$7,"1",$D34:$BG34) -> 15 | BJ34: =SUMIFS($D$9:$BG$9,$D$7:$BG$7,"1",$D34:$BG34,">"&-1) -> 15 | BK34: =ROUNDUP(IF(BJ34,BI34/BJ34%,0),2) -> 100 | BL34: =SUMIF($D$7:$BG$7,"2",$D34:$BG34) -> 24 | BM34: =SUMIFS($D$9:$BG$9,$D$7:$BG$7,"2",$D34:$BG34,">"&-1) -> 25 | BN34: =ROUNDUP(IF(BM34,BL34/BM34%,0),2) -> 96 | BO34: =SUMIF($D$7:$BG$7,"3",$D34:$BG34) -> 20 | BP34: =SUMIFS($D$9:$BG$9,$D$7:$BG$7,"3",$D34:$BG34,">"&-1) -> 20 | BQ34: =ROUNDUP(IF(BP34,BO34/BP34%,0),2) -> 100 | BR34: =SUMIF($D$7:$BG$7,"4",$D34:$BG34) -> 15 | BS34: =SUMIFS($D$9:$BG$9,$D$7:$BG$7,"4",$D34:$BG34,">"&-1) -> 15 | BT34: =ROUNDUP(IF(BS34,BR34/BS34%,0),2) -> 100 | BU34: =SUMIF($D$7:$BG$7,"5",$D34:$BG34) -> 14 | BV34: =SUMIFS($D$9:$BG$9,$D$7:$BG$7,"5",$D34:$BG34,">"&-1) -> 20 | BW34: =ROUNDUP(IF(BV34,BU34/BV34%,0),2) -> 70 | BX34: =SUMIF($D$7:$BG$7,"6",$D34:$BG34) -> 0 | BY34: =SUMIFS($D$9:$BG$9,$D$7:$BG$7,"6",$D34:$BG34,">"&-1) -> 0 | BZ34: =ROUNDUP(IF(BY34,BX34/BY34%,0),2) -> 0
A35: 23N81A6226 | D35: 5 | M35: 1 | Q35: 1 | U35: 5 | W35: 3 | X35: 2 | AC35: 2 | AE35: 1 | BA35: 10 | BB35: 10 | BC35: 10 | BD35: 10 | BE35: 10 | BI35: =SUMIF($D$7:$BG$7,"1",$D35:$BG35) -> 10 | BJ35: =SUMIFS($D$9:$BG$9,$D$7:$BG$7,"1",$D35:$BG35,">"&-1) -> 10 | BK35: =ROUNDUP(IF(BJ35,BI35/BJ35%,0),2) -> 100 | BL35: =SUMIF($D$7:$BG$7,"2",$D35:$BG35) -> 21 | BM35: =SUMIFS($D$9:$BG$9,$D$7:$BG$7,"2",$D35:$BG35,">"&-1) -> 22 | BN35: =ROUNDUP(IF(BM35,BL35/BM35%,0),2) -> 95.46 | BO35: =SUMIF($D$7:$BG$7,"3",$D35:$BG35) -> 18 | BP35: =SUMIFS($D$9:$BG$9,$D$7:$BG$7,"3",$D35:$BG35,">"&-1) -> 25 | BQ35: =ROUNDUP(IF(BP35,BO35/BP35%,0),2) -> 72 | BR35: =SUMIF($D$7:$BG$7,"4",$D35:$BG35) -> 10 | BS35: =SUMIFS($D$9:$BG$9,$D$7:$BG$7,"4",$D35:$BG35,">"&-1) -> 10 | BT35: =ROUNDUP(IF(BS35,BR35/BS35%,0),2) -> 100 | BU35: =SUMIF($D$7:$BG$7,"5",$D35:$BG35) -> 11 | BV35: =SUMIFS($D$9:$BG$9,$D$7:$BG$7,"5",$D35:$BG35,">"&-1) -> 15 | BW35: =ROUNDUP(IF(BV35,BU35/BV35%,0),2) -> 73.34 | BX35: =SUMIF($D$7:$BG$7,"6",$D35:$BG35) -> 0 | BY35: =SUMIFS($D$9:$BG$9,$D$7:$BG$7,"6",$D35:$BG35,">"&-1) -> 0 | BZ35: =ROUNDUP(IF(BY35,BX35/BY35%,0),2) -> 0
A36: 23N81A6227 | D36: 5 | W36: 3 | X36: 2 | Y36: 1 | BA36: 10 | BB36: 10 | BC36: 10 | BD36: 10 | BE36: 10 | BI36: =SUMIF($D$7:$BG$7,"1",$D36:$BG36) -> 10 | BJ36: =SUMIFS($D$9:$BG$9,$D$7:$BG$7,"1",$D36:$BG36,">"&-1) -> 10 | BK36: =ROUNDUP(IF(BJ36,BI36/BJ36%,0),2) -> 100 | BL36: =SUMIF($D$7:$BG$7,"2",$D36:$BG36) -> 20 | BM36: =SUMIFS($D$9:$BG$9,$D$7:$BG$7,"2",$D36:$BG36,">"&-1) -> 20 | BN36: =ROUNDUP(IF(BM36,BL36/BM36%,0),2) -> 100 | BO36: =SUMIF($D$7:$BG$7,"3",$D36:$BG36) -> 11 | BP36: =SUMIFS($D$9:$BG$9,$D$7:$BG$7,"3",$D36:$BG36,">"&-1) -> 15 | BQ36: =ROUNDUP(IF(BP36,BO36/BP36%,0),2) -> 73.34 | BR36: =SUMIF($D$7:$BG$7,"4",$D36:$BG36) -> 10 | BS36: =SUMIFS($D$9:$BG$9,$D$7:$BG$7,"4",$D36:$BG36,">"&-1) -> 10 | BT36: =ROUNDUP(IF(BS36,BR36/BS36%,0),2) -> 100 | BU36: =SUMIF($D$7:$BG$7,"5",$D36:$BG36) -> 10 | BV36: =SUMIFS($D$9:$BG$9,$D$7:$BG$7,"5",$D36:$BG36,">"&-1) -> 10 | BW36: =ROUNDUP(IF(BV36,BU36/BV36%,0),2) -> 100 | BX36: =SUMIF($D$7:$BG$7,"6",$D36:$BG36) -> 0 | BY36: =SUMIFS($D$9:$BG$9,$D$7:$BG$7,"6",$D36:$BG36,">"&-1) -> 0 | BZ36: =ROUNDUP(IF(BY36,BX36/BY36%,0),2) -> 0
A37: 23N81A6228 | D37: 5 | U37: 5 | W37: 3 | Y37: 1 | BA37: 10 | BB37: 10 | BC37: 10 | BD37: 10 | BE37: 10 | BI37: =SUMIF($D$7:$BG$7,"1",$D37:$BG37) -> 10 | BJ37: =SUMIFS($D$9:$BG$9,$D$7:$BG$7,"1",$D37:$BG37,">"&-1) -> 10 | BK37: =ROUNDUP(IF(BJ37,BI37/BJ37%,0),2) -> 100 | BL37: =SUMIF($D$7:$BG$7,"2",$D37:$BG37) -> 18 | BM37: =SUMIFS($D$9:$BG$9,$D$7:$BG$7,"2",$D37:$BG37,">"&-1) -> 18 | BN37: =ROUNDUP(IF(BM37,BL37/BM37%,0),2) -> 100 | BO37: =SUMIF($D$7:$BG$7,"3",$D37:$BG37) -> 16 | BP37: =SUMIFS($D$9:$BG$9,$D$7:$BG$7,"3",$D37:$BG37,">"&-1) -> 20 | BQ37: =ROUNDUP(IF(BP37,BO37/BP37%,0),2) -> 80 | BR37: =SUMIF($D$7:$BG$7,"4",$D37:$BG37) -> 10 | BS37: =SUMIFS($D$9:$BG$9,$D$7:$BG$7,"4",$D37:$BG37,">"&-1) -> 10 | BT37: =ROUNDUP(IF(BS37,BR37/BS37%,0),2) -> 100 | BU37: =SUMIF($D$7:$BG$7,"5",$D37:$BG37) -> 10 | BV37: =SUMIFS($D$9:$BG$9,$D$7:$BG$7,"5",$D37:$BG37,">"&-1) -> 10 | BW37: =ROUNDUP(IF(BV37,BU37/BV37%,0),2) -> 100 | BX37: =SUMIF($D$7:$BG$7,"6",$D37:$BG37) -> 0 | BY37: =SUMIFS($D$9:$BG$9,$D$7:$BG$7,"6",$D37:$BG37,">"&-1) -> 0 | BZ37: =ROUNDUP(IF(BY37,BX37/BY37%,0),2) -> 0
A38: 23N81A6229 | D38: 5 | U38: 2 | W38: 3 | X38: 2 | AE38: 2 | BA38: 5 | BB38: 5 | BC38: 5 | BD38: 5 | BE38: 5 | BI38: =SUMIF($D$7:$BG$7,"1",$D38:$BG38) -> 5 | BJ38: =SUMIFS($D$9:$BG$9,$D$7:$BG$7,"1",$D38:$BG38,">"&-1) -> 10 | BK38: =ROUNDUP(IF(BJ38,BI38/BJ38%,0),2) -> 50 | BL38: =SUMIF($D$7:$BG$7,"2",$D38:$BG38) -> 15 | BM38: =SUMIFS($D$9:$BG$9,$D$7:$BG$7,"2",$D38:$BG38,">"&-1) -> 20 | BN38: =ROUNDUP(IF(BM38,BL38/BM38%,0),2) -> 75 | BO38: =SUMIF($D$7:$BG$7,"3",$D38:$BG38) -> 9 | BP38: =SUMIFS($D$9:$BG$9,$D$7:$BG$7,"3",$D38:$BG38,">"&-1) -> 20 | BQ38: =ROUNDUP(IF(BP38,BO38/BP38%,0),2) -> 45 | BR38: =SUMIF($D$7:$BG$7,"4",$D38:$BG38) -> 5 | BS38: =SUMIFS($D$9:$BG$9,$D$7:$BG$7,"4",$D38:$BG38,">"&-1) -> 10 | BT38: =ROUNDUP(IF(BS38,BR38/BS38%,0),2) -> 50 | BU38: =SUMIF($D$7:$BG$7,"5",$D38:$BG38) -> 5 | BV38: =SUMIFS($D$9:$BG$9,$D$7:$BG$7,"5",$D38:$BG38,">"&-1) -> 10 | BW38: =ROUNDUP(IF(BV38,BU38/BV38%,0),2) -> 50 | BX38: =SUMIF($D$7:$BG$7,"6",$D38:$BG38) -> 0 | BY38: =SUMIFS($D$9:$BG$9,$D$7:$BG$7,"6",$D38:$BG38,">"&-1) -> 0 | BZ38: =ROUNDUP(IF(BY38,BX38/BY38%,0),2) -> 0
A39: 23N81A6230 | D39: 3 | J39: 2 | K39: 2 | N39: 4 | U39: 3 | W39: 3 | X39: 2 | AC39: 2 | BA39: 10 | BB39: 10 | BC39: 10 | BD39: 10 | BE39: 10 | BI39: =SUMIF($D$7:$BG$7,"1",$D39:$BG39) -> 14 | BJ39: =SUMIFS($D$9:$BG$9,$D$7:$BG$7,"1",$D39:$BG39,">"&-1) -> 15 | BK39: =ROUNDUP(IF(BJ39,BI39/BJ39%,0),2) -> 93.34 | BL39: =SUMIF($D$7:$BG$7,"2",$D39:$BG39) -> 18 | BM39: =SUMIFS($D$9:$BG$9,$D$7:$BG$7,"2",$D39:$BG39,">"&-1) -> 20 | BN39: =ROUNDUP(IF(BM39,BL39/BM39%,0),2) -> 90 | BO39: =SUMIF($D$7:$BG$7,"3",$D39:$BG39) -> 19 | BP39: =SUMIFS($D$9:$BG$9,$D$7:$BG$7,"3",$D39:$BG39,">"&-1) -> 25 | BQ39: =ROUNDUP(IF(BP39,BO39/BP39%,0),2) -> 76 | BR39: =SUMIF($D$7:$BG$7,"4",$D39:$BG39) -> 10 | BS39: =SUMIFS($D$9:$BG$9,$D$7:$BG$7,"4",$D39:$BG39,">"&-1) -> 10 | BT39: =ROUNDUP(IF(BS39,BR39/BS39%,0),2) -> 100 | BU39: =SUMIF($D$7:$BG$7,"5",$D39:$BG39) -> 10 | BV39: =SUMIFS($D$9:$BG$9,$D$7:$BG$7,"5",$D39:$BG39,">"&-1) -> 10 | BW39: =ROUNDUP(IF(BV39,BU39/BV39%,0),2) -> 100 | BX39: =SUMIF($D$7:$BG$7,"6",$D39:$BG39) -> 0 | BY39: =SUMIFS($D$9:$BG$9,$D$7:$BG$7,"6",$D39:$BG39,">"&-1) -> 0 | BZ39: =ROUNDUP(IF(BY39,BX39/BY39%,0),2) -> 0
A40: 23N81A6231 | D40: 5 | H40: 1 | K40: 1 | L40: 2 | M40: 2 | N40: 5 | P40: 2 | Q40: 2 | U40: 5 | W40: 3 | X40: 2 | Y40: 5 | AA40: 5 | AC40: 4 | BA40: 10 | BB40: 10 | BC40: 10 | BD40: 10 | BE40: 10 | BI40: =SUMIF($D$7:$BG$7,"1",$D40:$BG40) -> 11 | BJ40: =SUMIFS($D$9:$BG$9,$D$7:$BG$7,"1",$D40:$BG40,">"&-1) -> 12.5 | BK40: =ROUNDUP(IF(BJ40,BI40/BJ40%,0),2) -> 88 | BL40: =SUMIF($D$7:$BG$7,"2",$D40:$BG40) -> 25 | BM40: =SUMIFS($D$9:$BG$9,$D$7:$BG$7,"2",$D40:$BG40,">"&-1) -> 30 | BN40: =ROUNDUP(IF(BM40,BL40/BM40%,0),2) -> 83.34 | BO40: =SUMIF($D$7:$BG$7,"3",$D40:$BG40) -> 29 | BP40: =SUMIFS($D$9:$BG$9,$D$7:$BG$7,"3",$D40:$BG40,">"&-1) -> 30 | BQ40: =ROUNDUP(IF(BP40,BO40/BP40%,0),2) -> 96.67 | BR40: =SUMIF($D$7:$BG$7,"4",$D40:$BG40) -> 15 | BS40: =SUMIFS($D$9:$BG$9,$D$7:$BG$7,"4",$D40:$BG40,">"&-1) -> 15 | BT40: =ROUNDUP(IF(BS40,BR40/BS40%,0),2) -> 100 | BU40: =SUMIF($D$7:$BG$7,"5",$D40:$BG40) -> 14 | BV40: =SUMIFS($D$9:$BG$9,$D$7:$BG$7,"5",$D40:$BG40,">"&-1) -> 20 | BW40: =ROUNDUP(IF(BV40,BU40/BV40%,0),2) -> 70 | BX40: =SUMIF($D$7:$BG$7,"6",$D40:$BG40) -> 0 | BY40: =SUMIFS($D$9:$BG$9,$D$7:$BG$7,"6",$D40:$BG40,">"&-1) -> 0 | BZ40: =ROUNDUP(IF(BY40,BX40/BY40%,0),2) -> 0
...

Sheet SEE Marks
BK1: ='IA Marks'!BJ1 -> LEVEL 1: | BL1: 60 | BM1: % students rated more than or equal to
B2: % of students scoring greater than or equal to | BK2: ='IA Marks'!BJ2 -> LEVEL 2: | BL2: 70
A3: IF(D8<IA!BA1,0,IF(D8>=IA!BA3,3,IF(D8>=IA!BA2,2,1))) | B3: % of Max. Marks | D3: Department of Computer Science and Engineering - Cyber Security Program | BK3: ='IA Marks'!BJ3 -> LEVEL 3: | BL3: 80
B4: of marks | D4: Academic Year : | M4: ='IA Marks'!AI5&"/"&'IA Marks'!AP4 -> Computer Organization and Architecture/S23CY304PC | Z4: Semester: | AB4: {='IA Marks'!AC4:AE4} -> #VALUE! | AE4: DIV: | AG4: Course Code: | AM4: {='IA Marks'!AP4:AQ4} -> #VALUE! | AP4: Student Count | AV4: {='IA Marks'!AY4:AZ4} -> #VALUE!
D5: Name of Course Teacher: | I5: ='IA Marks'!J5:S5 | S5: Set Target: | Z5: 75 | AA5: Course Name: | AF5: {='IA Marks'!AI5:AZ5} -> #VALUE! | BO5: =BI1&BL1&""&BM1&""&Z5&BJ1 -> 60% students rated more than or equal to 75
A6: USN | B6: Name | D6: SEE Marks
C7: CO Mapped | D7: 1 | E7: 2 | F7: 3 | G7: 4 | H7: 5 | I7: 6
C8: Q. No. | AI8: CO1 | AL8: CO2 | AO8: CO3 | AR8: CO4 | AU8: CO5 | AX8: CO6
C9: Max. Marks | D9: 60 | E9: 60 | F9: 60 | G9: 60 | H9: 60 | I9: 60 | AI9: Level | AK9: =IFERROR(IF(AK10<BL1,0,IF(AK10>=BL3,3,IF(AK10>=BL2,2,1))),0) -> 3 | AL9: Level | AN9: =IFERROR(IF(AN10<BL1,0,IF(AN10>=BL3,3,IF(AN10>=BL2,2,1))),0) -> 3 | AO9: Level | AQ9: =IFERROR(IF(AQ10<BL1,0,IF(AQ10>=BL3,3,IF(AQ10>=BL2,2,1))),0) -> 3 | AR9: Level | AT9: =IFERROR(IF(AT10<BL1,0,IF(AT10>=BL3,3,IF(AT10>=BL2,2,1))),0) -> 3 | AU9: Level | AW9: =IFERROR(IF(AW10<BL1,0,IF(AW10>=BL3,3,IF(AW10>=BL2,2,1))),0) -> 3 | AX9: Level | AZ9: =IFERROR(IF(AZ10<BL1,0,IF(AZ10>=BL3,3,IF(AZ10>=BL2,2,1))),0) -> 3
AI10: Percentage | AK10: =IFERROR(AK11/AI11*100,0) -> 100 | AL10: Percentage | AN10: =IFERROR(AN11/AL11*100,0) -> 100 | AO10: Percentage | AQ10: =IFERROR(AQ11/AO11*100,0) -> 100 | AR10: Percentage | AT10: =IFERROR(AT11/AR11*100,0) -> 100 | AU10: Percentage | AW10: =IFERROR(AW11/AU11*100,0) -> 100 | AX10: Percentage | AZ10: =IFERROR(AZ11/AX11*100,0) -> 100
AI11: =COUNTIF(AI13:AI200,">"&0) -> 123 | AK11: =COUNTIF(AK13:AK200,">="&Z5) -> 123 | AL11: =COUNTIF(AL13:AL200,">"&0) -> 123 | AN11: =COUNTIF(AN13:AN200,">="&Z5) -> 123 | AO11: =COUNTIF(AO13:AO200,">"&0) -> 123 | AQ11: =COUNTIF(AQ13:AQ200,">="&Z5) -> 123 | AR11: =COUNTIF(AR13:AR200,">"&0) -> 123 | AT11: =COUNTIF(AT13:AT200,">="&Z5) -> 123 | AU11: =COUNTIF(AU13:AU200,">"&0) -> 123 | AW11: =COUNTIF(AW13:AW200,">="&Z5) -> 123 | AX11: =COUNTIF(AX13:AX200,">"&0) -> 123 | AZ11: =COUNTIF(AZ13:AZ200,">="&Z5) -> 123
AI12: SUM | AJ12: COUNT | AK12: % | AL12: SUM | AM12: COUNT | AN12: % | AO12: SUM | AP12: COUNT | AQ12: % | AR12: SUM | AS12: COUNT | AT12: % | AU12: SUM | AV12: COUNT | AW12: % | AX12: SUM | AY12: COUNT | AZ12: %
A13: ='IA Marks'!A13 -> 23N81A6201 | B13: ='IA Marks'!B13 -> 0 | D13: 45 | E13: 45 | F13: 45 | G13: 45 | H13: 45 | I13: 45 | AI13: =SUMIF($D$7:$Z$7,"1",D13:Z13) -> 45 | AJ13: =SUMIFS($D$9:$Z$9,$D$7:$Z$7,"1",D13:Z13,">"&-1) -> 60 | AK13: =ROUNDUP(IF(AJ13,AI13/AJ13%,0),2) -> 75 | AL13: =SUMIF($D$7:$Z$7,"2",D13:Z13) -> 45 | AM13: =SUMIFS($D$9:$Z$9,$D$7:$Z$7,"2",D13:Z13,">"&-1) -> 60 | AN13: =ROUNDUP(IF(AM13,AL13/AM13%,0),2) -> 75 | AO13: =SUMIF($D$7:$Z$7,"3",D13:Z13) -> 45 | AP13: =SUMIFS($D$9:$Z$9,$D$7:$Z$7,"3",D13:Z13,">"&-1) -> 60 | AQ13: =ROUNDUP(IF(AP13,AO13/AP13%,0),2) -> 75 | AR13: =SUMIF($D$7:$Z$7,"4",D13:Z13) -> 45 | AS13: =SUMIFS($D$9:$Z$9,$D$7:$Z$7,"4",D13:Z13,">"&-1) -> 60 | AT13: =ROUNDUP(IF(AS13,AR13/AS13%,0),2) -> 75 | AU13: =SUMIF($D$7:$Z$7,"5",D13:Z13) -> 45 | AV13: =SUMIFS($D$9:$Z$9,$D$7:$Z$7,"5",D13:Z13,">"&-1) -> 60 | AW13: =ROUNDUP(IF(AV13,AU13/AV13%,0),2) -> 75 | AX13: =SUMIF($D$7:$Z$7,"6",D13:Z13) -> 45 | AY13: =SUMIFS($D$9:$Z$9,$D$7:$Z$7,"6",D13:Z13,">"&-1) -> 60 | AZ13: =ROUNDUP(IF(AY13,AX13/AY13%,0),2) -> 75
A14: ='IA Marks'!A14 -> 23N81A6202 | B14: ='IA Marks'!B14 -> 0 | D14: 45 | E14: 45 | F14: 45 | G14: 45 | H14: 45 | I14: 45 | AI14: =SUMIF($D$7:$Z$7,"1",D14:Z14) -> 45 | AJ14: =SUMIFS($D$9:$Z$9,$D$7:$Z$7,"1",D14:Z14,">"&-1) -> 60 | AK14: =ROUNDUP(IF(AJ14,AI14/AJ14%,0),2) -> 75 | AL14: =SUMIF($D$7:$Z$7,"2",D14:Z14) -> 45 | AM14: =SUMIFS($D$9:$Z$9,$D$7:$Z$7,"2",D14:Z14,">"&-1) -> 60 | AN14: =ROUNDUP(IF(AM14,AL14/AM14%,0),2) -> 75 | AO14: =SUMIF($D$7:$Z$7,"3",D14:Z14) -> 45 | AP14: =SUMIFS($D$9:$Z$9,$D$7:$Z$7,"3",D14:Z14,">"&-1) -> 60 | AQ14: =ROUNDUP(IF(AP14,AO14/AP14%,0),2) -> 75 | AR14: =SUMIF($D$7:$Z$7,"4",D14:Z14) -> 45 | AS14: =SUMIFS($D$9:$Z$9,$D$7:$Z$7,"4",D14:Z14,">"&-1) -> 60 | AT14: =ROUNDUP(IF(AS14,AR14/AS14%,0),2) -> 75 | AU14: =SUMIF($D$7:$Z$7,"5",D14:Z14) -> 45 | AV14: =SUMIFS($D$9:$Z$9,$D$7:$Z$7,"5",D14:Z14,">"&-1) -> 60 | AW14: =ROUNDUP(IF(AV14,AU14/AV14%,0),2) -> 75 | AX14: =SUMIF($D$7:$Z$7,"6",D14:Z14) -> 45 | AY14: =SUMIFS($D$9:$Z$9,$D$7:$Z$7,"6",D14:Z14,">"&-1) -> 60 | AZ14: =ROUNDUP(IF(AY14,AX14/AY14%,0),2) -> 75
A15: ='IA Marks'!A15 -> 23N81A6203 | B15: ='IA Marks'!B15 -> 0 | D15: 45 | E15: 45 | F15: 45 | G15: 45 | H15: 45 | I15: 45 | AI15: =SUMIF($D$7:$Z$7,"1",D15:Z15) -> 45 | AJ15: =SUMIFS($D$9:$Z$9,$D$7:$Z$7,"1",D15:Z15,">"&-1) -> 60 | AK15: =ROUNDUP(IF(AJ15,AI15/AJ15%,0),2) -> 75 | AL15: =SUMIF($D$7:$Z$7,"2",D15:Z15) -> 45 | AM15: =SUMIFS($D$9:$Z$9,$D$7:$Z$7,"2",D15:Z15,">"&-1) -> 60 | AN15: =ROUNDUP(IF(AM15,AL15/AM15%,0),2) -> 75 | AO15: =SUMIF($D$7:$Z$7,"3",D15:Z15) -> 45 | AP15: =SUMIFS($D$9:$Z$9,$D$7:$Z$7,"3",D15:Z15,">"&-1) -> 60 | AQ15: =ROUNDUP(IF(AP15,AO15/AP15%,0),2) -> 75 | AR15: =SUMIF($D$7:$Z$7,"4",D15:Z15) -> 45 | AS15: =SUMIFS($D$9:$Z$9,$D$7:$Z$7,"4",D15:Z15,">"&-1) -> 60 | AT15: =ROUNDUP(IF(AS15,AR15/AS15%,0),2) -> 75 | AU15: =SUMIF($D$7:$Z$7,"5",D15:Z15) -> 45 | AV15: =SUMIFS($D$9:$Z$9,$D$7:$Z$7,"5",D15:Z15,">"&-1) -> 60 | AW15: =ROUNDUP(IF(AV15,AU15/AV15%,0),2) -> 75 | AX15: =SUMIF($D$7:$Z$7,"6",D15:Z15) -> 45 | AY15: =SUMIFS($D$9:$Z$9,$D$7:$Z$7,"6",D15:Z15,">"&-1) -> 60 | AZ15: =ROUNDUP(IF(AY15,AX15/AY15%,0),2) -> 75
A16: ='IA Marks'!A16 -> 23N81A6204 | B16: ='IA Marks'!B16 -> 0 | D16: 45 | E16: 45 | F16: 45 | G16: 45 | H16: 45 | I16: 45 | AI16: =SUMIF($D$7:$Z$7,"1",D16:Z16) -> 45 | AJ16: =SUMIFS($D$9:$Z$9,$D$7:$Z$7,"1",D16:Z16,">"&-1) -> 60 | AK16: =ROUNDUP(IF(AJ16,AI16/AJ16%,0),2) -> 75 | AL16: =SUMIF($D$7:$Z$7,"2",D16:Z16) -> 45 | AM16: =SUMIFS($D$9:$Z$9,$D$7:$Z$7,"2",D16:Z16,">"&-1) -> 60 | AN16: =ROUNDUP(IF(AM16,AL16/AM16%,0),2) -> 75 | AO16: =SUMIF($D$7:$Z$7,"3",D16:Z16) -> 45 | AP16: =SUMIFS($D$9:$Z$9,$D$7:$Z$7,"3",D16:Z16,">"&-1) -> 60 | AQ16: =ROUNDUP(IF(AP16,AO16/AP16%,0),2) -> 75 | AR16: =SUMIF($D$7:$Z$7,"4",D16:Z16) -> 45 | AS16: =SUMIFS($D$9:$Z$9,$D$7:$Z$7,"4",D16:Z16,">"&-1) -> 60 | AT16: =ROUNDUP(IF(AS16,AR16/AS16%,0),2) -> 75 | AU16: =SUMIF($D$7:$Z$7,"5",D16:Z16) -> 45 | AV16: =SUMIFS($D$9:$Z$9,$D$7:$Z$7,"5",D16:Z16,">"&-1) -> 60 | AW16: =ROUNDUP(IF(AV16,AU16/AV16%,0),2) -> 75 | AX16: =SUMIF($D$7:$Z$7,"6",D16:Z16) -> 45 | AY16: =SUMIFS($D$9:$Z$9,$D$7:$Z$7,"6",D16:Z16,">"&-1) -> 60 | AZ16: =ROUNDUP(IF(AY16,AX16/AY16%,0),2) -> 75
A17: ='IA Marks'!A17 -> 23N81A6205 | B17: ='IA Marks'!B17 -> 0 | D17: 45 | E17: 45 | F17: 45 | G17: 45 | H17: 45 | I17: 45 | AI17: =SUMIF($D$7:$Z$7,"1",D17:Z17) -> 45 | AJ17: =SUMIFS($D$9:$Z$9,$D$7:$Z$7,"1",D17:Z17,">"&-1) -> 60 | AK17: =ROUNDUP(IF(AJ17,AI17/AJ17%,0),2) -> 75 | AL17: =SUMIF($D$7:$Z$7,"2",D17:Z17) -> 45 | AM17: =SUMIFS($D$9:$Z$9,$D$7:$Z$7,"2",D17:Z17,">"&-1) -> 60 | AN17: =ROUNDUP(IF(AM17,AL17/AM17%,0),2) -> 75 | AO17: =SUMIF($D$7:$Z$7,"3",D17:Z17) -> 45 | AP17: =SUMIFS($D$9:$Z$9,$D$7:$Z$7,"3",D17:Z17,">"&-1) -> 60 | AQ17: =ROUNDUP(IF(AP17,AO17/AP17%,0),2) -> 75 | AR17: =SUMIF($D$7:$Z$7,"4",D17:Z17) -> 45 | AS17: =SUMIFS($D$9:$Z$9,$D$7:$Z$7,"4",D17:Z17,">"&-1) -> 60 | AT17: =ROUNDUP(IF(AS17,AR17/AS17%,0),2) -> 75 | AU17: =SUMIF($D$7:$Z$7,"5",D17:Z17) -> 45 | AV17: =SUMIFS($D$9:$Z$9,$D$7:$Z$7,"5",D17:Z17,">"&-1) -> 60 | AW17: =ROUNDUP(IF(AV17,AU17/AV17%,0),2) -> 75 | AX17: =SUMIF($D$7:$Z$7,"6",D17:Z17) -> 45 | AY17: =SUMIFS($D$9:$Z$9,$D$7:$Z$7,"6",D17:Z17,">"&-1) -> 60 | AZ17: =ROUNDUP(IF(AY17,AX17/AY17%,0),2) -> 75
A18: ='IA Marks'!A18 -> 23N81A6206 | B18: ='IA Marks'!B18 -> 0 | D18: 45 | E18: 45 | F18: 45 | G18: 45 | H18: 45 | I18: 45 | AI18: =SUMIF($D$7:$Z$7,"1",D18:Z18) -> 45 | AJ18: =SUMIFS($D$9:$Z$9,$D$7:$Z$7,"1",D18:Z18,">"&-1) -> 60 | AK18: =ROUNDUP(IF(AJ18,AI18/AJ18%,0),2) -> 75 | AL18: =SUMIF($D$7:$Z$7,"2",D18:Z18) -> 45 | AM18: =SUMIFS($D$9:$Z$9,$D$7:$Z$7,"2",D18:Z18,">"&-1) -> 60 | AN18: =ROUNDUP(IF(AM18,AL18/AM18%,0),2) -> 75 | AO18: =SUMIF($D$7:$Z$7,"3",D18:Z18) -> 45 | AP18: =SUMIFS($D$9:$Z$9,$D$7:$Z$7,"3",D18:Z18,">"&-1) -> 60 | AQ18: =ROUNDUP(IF(AP18,AO18/AP18%,0),2) -> 75 | AR18: =SUMIF($D$7:$Z$7,"4",D18:Z18) -> 45 | AS18: =SUMIFS($D$9:$Z$9,$D$7:$Z$7,"4",D18:Z18,">"&-1) -> 60 | AT18: =ROUNDUP(IF(AS18,AR18/AS18%,0),2) -> 75 | AU18: =SUMIF($D$7:$Z$7,"5",D18:Z18) -> 45 | AV18: =SUMIFS($D$9:$Z$9,$D$7:$Z$7,"5",D18:Z18,">"&-1) -> 60 | AW18: =ROUNDUP(IF(AV18,AU18/AV18%,0),2) -> 75 | AX18: =SUMIF($D$7:$Z$7,"6",D18:Z18) -> 45 | AY18: =SUMIFS($D$9:$Z$9,$D$7:$Z$7,"6",D18:Z18,">"&-1) -> 60 | AZ18: =ROUNDUP(IF(AY18,AX18/AY18%,0),2) -> 75
A19: ='IA Marks'!A19 -> 23N81A6207 | B19: ='IA Marks'!B19 -> 0 | D19: 45 | E19: 45 | F19: 45 | G19: 45 | H19: 45 | I19: 45 | AI19: =SUMIF($D$7:$Z$7,"1",D19:Z19) -> 45 | AJ19: =SUMIFS($D$9:$Z$9,$D$7:$Z$7,"1",D19:Z19,">"&-1) -> 60 | AK19: =ROUNDUP(IF(AJ19,AI19/AJ19%,0),2) -> 75 | AL19: =SUMIF($D$7:$Z$7,"2",D19:Z19) -> 45 | AM19: =SUMIFS($D$9:$Z$9,$D$7:$Z$7,"2",D19:Z19,">"&-1) -> 60 | AN19: =ROUNDUP(IF(AM19,AL19/AM19%,0),2) -> 75 | AO19: =SUMIF($D$7:$Z$7,"3",D19:Z19) -> 45 | AP19: =SUMIFS($D$9:$Z$9,$D$7:$Z$7,"3",D19:Z19,">"&-1) -> 60 | AQ19: =ROUNDUP(IF(AP19,AO19/AP19%,0),2) -> 75 | AR19: =SUMIF($D$7:$Z$7,"4",D19:Z19) -> 45 | AS19: =SUMIFS($D$9:$Z$9,$D$7:$Z$7,"4",D19:Z19,">"&-1) -> 60 | AT19: =ROUNDUP(IF(AS19,AR19/AS19%,0),2) -> 75 | AU19: =SUMIF($D$7:$Z$7,"5",D19:Z19) -> 45 | AV19: =SUMIFS($D$9:$Z$9,$D$7:$Z$7,"5",D19:Z19,">"&-1) -> 60 | AW19: =ROUNDUP(IF(AV19,AU19/AV19%,0),2) -> 75 | AX19: =SUMIF($D$7:$Z$7,"6",D19:Z19) -> 45 | AY19: =SUMIFS($D$9:$Z$9,$D$7:$Z$7,"6",D19:Z19,">"&-1) -> 60 | AZ19: =ROUNDUP(IF(AY19,AX19/AY19%,0),2) -> 75
A20: ='IA Marks'!A20 -> 23N81A6208 | B20: ='IA Marks'!B20 -> 0 | D20: 45 | E20: 45 | F20: 45 | G20: 45 | H20: 45 | I20: 45 | AI20: =SUMIF($D$7:$Z$7,"1",D20:Z20) -> 45 | AJ20: =SUMIFS($D$9:$Z$9,$D$7:$Z$7,"1",D20:Z20,">"&-1) -> 60 | AK20: =ROUNDUP(IF(AJ20,AI20/AJ20%,0),2) -> 75 | AL20: =SUMIF($D$7:$Z$7,"2",D20:Z20) -> 45 | AM20: =SUMIFS($D$9:$Z$9,$D$7:$Z$7,"2",D20:Z20,">"&-1) -> 60 | AN20: =ROUNDUP(IF(AM20,AL20/AM20%,0),2) -> 75 | AO20: =SUMIF($D$7:$Z$7,"3",D20:Z20) -> 45 | AP20: =SUMIFS($D$9:$Z$9,$D$7:$Z$7,"3",D20:Z20,">"&-1) -> 60 | AQ20: =ROUNDUP(IF(AP20,AO20/AP20%,0),2) -> 75 | AR20: =SUMIF($D$7:$Z$7,"4",D20:Z20) -> 45 | AS20: =SUMIFS($D$9:$Z$9,$D$7:$Z$7,"4",D20:Z20,">"&-1) -> 60 | AT20: =ROUNDUP(IF(AS20,AR20/AS20%,0),2) -> 75 | AU20: =SUMIF($D$7:$Z$7,"5",D20:Z20) -> 45 | AV20: =SUMIFS($D$9:$Z$9,$D$7:$Z$7,"5",D20:Z20,">"&-1) -> 60 | AW20: =ROUNDUP(IF(AV20,AU20/AV20%,0),2) -> 75 | AX20: =SUMIF($D$7:$Z$7,"6",D20:Z20) -> 45 | AY20: =SUMIFS($D$9:$Z$9,$D$7:$Z$7,"6",D20:Z20,">"&-1) -> 60 | AZ20: =ROUNDUP(IF(AY20,AX20/AY20%,0),2) -> 75
A21: ='IA Marks'!A21 -> 23N81A6209 | B21: ='IA Marks'!B21 -> 0 | D21: 45 | E21: 45 | F21: 45 | G21: 45 | H21: 45 | I21: 45 | AI21: =SUMIF($D$7:$Z$7,"1",D21:Z21) -> 45 | AJ21: =SUMIFS($D$9:$Z$9,$D$7:$Z$7,"1",D21:Z21,">"&-1) -> 60 | AK21: =ROUNDUP(IF(AJ21,AI21/AJ21%,0),2) -> 75 | AL21: =SUMIF($D$7:$Z$7,"2",D21:Z21) -> 45 | AM21: =SUMIFS($D$9:$Z$9,$D$7:$Z$7,"2",D21:Z21,">"&-1) -> 60 | AN21: =ROUNDUP(IF(AM21,AL21/AM21%,0),2) -> 75 | AO21: =SUMIF($D$7:$Z$7,"3",D21:Z21) -> 45 | AP21: =SUMIFS($D$9:$Z$9,$D$7:$Z$7,"3",D21:Z21,">"&-1) -> 60 | AQ21: =ROUNDUP(IF(AP21,AO21/AP21%,0),2) -> 75 | AR21: =SUMIF($D$7:$Z$7,"4",D21:Z21) -> 45 | AS21: =SUMIFS($D$9:$Z$9,$D$7:$Z$7,"4",D21:Z21,">"&-1) -> 60 | AT21: =ROUNDUP(IF(AS21,AR21/AS21%,0),2) -> 75 | AU21: =SUMIF($D$7:$Z$7,"5",D21:Z21) -> 45 | AV21: =SUMIFS($D$9:$Z$9,$D$7:$Z$7,"5",D21:Z21,">"&-1) -> 60 | AW21: =ROUNDUP(IF(AV21,AU21/AV21%,0),2) -> 75 | AX21: =SUMIF($D$7:$Z$7,"6",D21:Z21) -> 45 | AY21: =SUMIFS($D$9:$Z$9,$D$7:$Z$7,"6",D21:Z21,">"&-1) -> 60 | AZ21: =ROUNDUP(IF(AY21,AX21/AY21%,0),2) -> 75
A22: ='IA Marks'!A22 -> 23N81A6210 | B22: ='IA Marks'!B22 -> 0 | D22: 45 | E22: 45 | F22: 45 | G22: 45 | H22: 45 | I22: 45 | AI22: =SUMIF($D$7:$Z$7,"1",D22:Z22) -> 45 | AJ22: =SUMIFS($D$9:$Z$9,$D$7:$Z$7,"1",D22:Z22,">"&-1) -> 60 | AK22: =ROUNDUP(IF(AJ22,AI22/AJ22%,0),2) -> 75 | AL22: =SUMIF($D$7:$Z$7,"2",D22:Z22) -> 45 | AM22: =SUMIFS($D$9:$Z$9,$D$7:$Z$7,"2",D22:Z22,">"&-1) -> 60 | AN22: =ROUNDUP(IF(AM22,AL22/AM22%,0),2) -> 75 | AO22: =SUMIF($D$7:$Z$7,"3",D22:Z22) -> 45 | AP22: =SUMIFS($D$9:$Z$9,$D$7:$Z$7,"3",D22:Z22,">"&-1) -> 60 | AQ22: =ROUNDUP(IF(AP22,AO22/AP22%,0),2) -> 75 | AR22: =SUMIF($D$7:$Z$7,"4",D22:Z22) -> 45 | AS22: =SUMIFS($D$9:$Z$9,$D$7:$Z$7,"4",D22:Z22,">"&-1) -> 60 | AT22: =ROUNDUP(IF(AS22,AR22/AS22%,0),2) -> 75 | AU22: =SUMIF($D$7:$Z$7,"5",D22:Z22) -> 45 | AV22: =SUMIFS($D$9:$Z$9,$D$7:$Z$7,"5",D22:Z22,">"&-1) -> 60 | AW22: =ROUNDUP(IF(AV22,AU22/AV22%,0),2) -> 75 | AX22: =SUMIF($D$7:$Z$7,"6",D22:Z22) -> 45 | AY22: =SUMIFS($D$9:$Z$9,$D$7:$Z$7,"6",D22:Z22,">"&-1) -> 60 | AZ22: =ROUNDUP(IF(AY22,AX22/AY22%,0),2) -> 75
A23: ='IA Marks'!A23 -> 23N81A6211 | B23: ='IA Marks'!B23 -> 0 | D23: 45 | E23: 45 | F23: 45 | G23: 45 | H23: 45 | I23: 45 | AI23: =SUMIF($D$7:$Z$7,"1",D23:Z23) -> 45 | AJ23: =SUMIFS($D$9:$Z$9,$D$7:$Z$7,"1",D23:Z23,">"&-1) -> 60 | AK23: =ROUNDUP(IF(AJ23,AI23/AJ23%,0),2) -> 75 | AL23: =SUMIF($D$7:$Z$7,"2",D23:Z23) -> 45 | AM23: =SUMIFS($D$9:$Z$9,$D$7:$Z$7,"2",D23:Z23,">"&-1) -> 60 | AN23: =ROUNDUP(IF(AM23,AL23/AM23%,0),2) -> 75 | AO23: =SUMIF($D$7:$Z$7,"3",D23:Z23) -> 45 | AP23: =SUMIFS($D$9:$Z$9,$D$7:$Z$7,"3",D23:Z23,">"&-1) -> 60 | AQ23: =ROUNDUP(IF(AP23,AO23/AP23%,0),2) -> 75 | AR23: =SUMIF($D$7:$Z$7,"4",D23:Z23) -> 45 | AS23: =SUMIFS($D$9:$Z$9,$D$7:$Z$7,"4",D23:Z23,">"&-1) -> 60 | AT23: =ROUNDUP(IF(AS23,AR23/AS23%,0),2) -> 75 | AU23: =SUMIF($D$7:$Z$7,"5",D23:Z23) -> 45 | AV23: =SUMIFS($D$9:$Z$9,$D$7:$Z$7,"5",D23:Z23,">"&-1) -> 60 | AW23: =ROUNDUP(IF(AV23,AU23/AV23%,0),2) -> 75 | AX23: =SUMIF($D$7:$Z$7,"6",D23:Z23) -> 45 | AY23: =SUMIFS($D$9:$Z$9,$D$7:$Z$7,"6",D23:Z23,">"&-1) -> 60 | AZ23: =ROUNDUP(IF(AY23,AX23/AY23%,0),2) -> 75
A24: ='IA Marks'!A24 -> 23N81A6212 | B24: ='IA Marks'!B24 -> 0 | D24: 45 | E24: 45 | F24: 45 | G24: 45 | H24: 45 | I24: 45 | AI24: =SUMIF($D$7:$Z$7,"1",D24:Z24) -> 45 | AJ24: =SUMIFS($D$9:$Z$9,$D$7:$Z$7,"1",D24:Z24,">"&-1) -> 60 | AK24: =ROUNDUP(IF(AJ24,AI24/AJ24%,0),2) -> 75 | AL24: =SUMIF($D$7:$Z$7,"2",D24:Z24) -> 45 | AM24: =SUMIFS($D$9:$Z$9,$D$7:$Z$7,"2",D24:Z24,">"&-1) -> 60 | AN24: =ROUNDUP(IF(AM24,AL24/AM24%,0),2) -> 75 | AO24: =SUMIF($D$7:$Z$7,"3",D24:Z24) -> 45 | AP24: =SUMIFS($D$9:$Z$9,$D$7:$Z$7,"3",D24:Z24,">"&-1) -> 60 | AQ24: =ROUNDUP(IF(AP24,AO24/AP24%,0),2) -> 75 | AR24: =SUMIF($D$7:$Z$7,"4",D24:Z24) -> 45 | AS24: =SUMIFS($D$9:$Z$9,$D$7:$Z$7,"4",D24:Z24,">"&-1) -> 60 | AT24: =ROUNDUP(IF(AS24,AR24/AS24%,0),2) -> 75 | AU24: =SUMIF($D$7:$Z$7,"5",D24:Z24) -> 45 | AV24: =SUMIFS($D$9:$Z$9,$D$7:$Z$7,"5",D24:Z24,">"&-1) -> 60 | AW24: =ROUNDUP(IF(AV24,AU24/AV24%,0),2) -> 75 | AX24: =SUMIF($D$7:$Z$7,"6",D24:Z24) -> 45 | AY24: =SUMIFS($D$9:$Z$9,$D$7:$Z$7,"6",D24:Z24,">"&-1) -> 60 | AZ24: =ROUNDUP(IF(AY24,AX24/AY24%,0),2) -> 75
... A135: ='IA Marks'!A135 -> 0 | B135: ='IA Marks'!B135 -> 0 | D135: 45 | E135: 45 | F135: 45 | G135: 45 | H135: 45 | I135: 45 | AI135: =SUMIF($D$7:$Z$7,"1",D135:Z135) -> 45 | AJ135: =SUMIFS($D$9:$Z$9,$D$7:$Z$7,"1",D135:Z135,">"&-1) -> 60 | AK135: =ROUNDUP(IF(AJ135,AI135/AJ135%,0),2) -> 75 | AL135: =SUMIF($D$7:$Z$7,"2",D135:Z135) -> 45 | AM135: =SUMIFS($D$9:$Z$9,$D$7:$Z$7,"2",D135:Z135,">"&-1) -> 60 | AN135: =ROUNDUP(IF(AM135,AL135/AM135%,0),2) -> 75 | AO135: =SUMIF($D$7:$Z$7,"3",D135:Z135) -> 45 | AP135: =SUMIFS($D$9:$Z$9,$D$7:$Z$7,"3",D135:Z135,">"&-1) -> 60 | AQ135: =ROUNDUP(IF(AP135,AO135/AP135%,0),2) -> 75 | AR135: =SUMIF($D$7:$Z$7,"4",D135:Z135) -> 45 | AS135: =SUMIFS($D$9:$Z$9,$D$7:$Z$7,"4",D135:Z135,">"&-1) -> 60 | AT135: =ROUNDUP(IF(AS135,AR135/AS135%,0),2) -> 75 | AU135: =SUMIF($D$7:$Z$7,"5",D135:Z135) -> 45 | AV135: =SUMIFS($D$9:$Z$9,$D$7:$Z$7,"5",D135:Z135,">"&-1) -> 60 | AW135: =ROUNDUP(IF(AV135,AU135/AV135%,0),2) -> 75 | AX135: =SUMIF($D$7:$Z$7,"6",D135:Z135) -> 45 | AY135: =SUMIFS($D$9:$Z$9,$D$7:$Z$7,"6",D135:Z135,">"&-1) -> 60 | AZ135: =ROUNDUP(IF(AY135,AX135/AY135%,0),2) -> 75
BG136: =SUM(D136:R136) -> 0 | BH136: =(BG136*15)/40 -> 0 | BJ136: =SUMIF($D$7:$AG$7,"1",$D136:$BH136) -> 0 | BK136: =SUMIFS($D$9:$AG$9,$D$7:$AG$7,"1",$D136:$BH136,">"&-1) -> #VALUE! | BL136: =ROUNDUP(IF(BK136,BJ136/BK136%,0),2) -> #VALUE! | BM136: =SUMIF($D$7:$AG$7,"2",$D136:$BH136) -> 0 | BN136: =SUMIFS($D$9:$AG$9,$D$7:$AG$7,"2",$D136:$BH136,">"&-1) -> #VALUE! | BO136: =ROUNDUP(IF(BN136,BM136/BN136%,0),2) -> #VALUE! | BP136: =SUMIF($D$7:$AG$7,"3",$D136:$BH136) -> 0 | BQ136: =SUMIFS($D$9:$AG$9,$D$7:$AG$7,"3",$D136:$BH136,">"&-1) -> #VALUE! | BR136: =ROUNDUP(IF(BQ136,BP136/BQ136%,0),2) -> #VALUE! | BS136: =SUMIF($D$7:$AG$7,"4",$D136:$BH136) -> 0 | BT136: =SUMIFS($D$9:$AG$9,$D$7:$AG$7,"4",$D136:$BH136,">"&-1) -> #VALUE! | BU136: =ROUNDUP(IF(BT136,BS136/BT136%,0),2) -> #VALUE! | BV136: =SUMIF($D$7:$AG$7,"5",$D136:$BH136) -> 0 | BW136: =SUMIFS($D$9:$AG$9,$D$7:$AG$7,"5",$D136:$BH136,">"&-1) -> #VALUE! | BX136: =ROUNDUP(IF(BW136,BV136/BW136%,0),2) -> #VALUE! | BY136: =SUMIF($D$7:$AG$7,"6",$D136:$BH136) -> 0 | BZ136: =SUMIFS($D$9:$AG$9,$D$7:$AG$7,"6",$D136:$BH136,">"&-1) -> #VALUE! | CA136: =ROUNDUP(IF(BZ136,BY136/BZ136%,0),2) -> #VALUE!
BG137: =SUM(D137:R137) -> 0 | BH137: =(BG137*15)/40 -> 0 | BJ137: =SUMIF($D$7:$AG$7,"1",$D137:$BH137) -> 0 | BK137: =SUMIFS($D$9:$AG$9,$D$7:$AG$7,"1",$D137:$BH137,">"&-1) -> #VALUE! | BL137: =ROUNDUP(IF(BK137,BJ137/BK137%,0),2) -> #VALUE! | BM137: =SUMIF($D$7:$AG$7,"2",$D137:$BH137) -> 0 | BN137: =SUMIFS($D$9:$AG$9,$D$7:$AG$7,"2",$D137:$BH137,">"&-1) -> #VALUE! | BO137: =ROUNDUP(IF(BN137,BM137/BN137%,0),2) -> #VALUE! | BP137: =SUMIF($D$7:$AG$7,"3",$D137:$BH137) -> 0 | BQ137: =SUMIFS($D$9:$AG$9,$D$7:$AG$7,"3",$D137:$BH137,">"&-1) -> #VALUE! | BR137: =ROUNDUP(IF(BQ137,BP137/BQ137%,0),2) -> #VALUE! | BS137: =SUMIF($D$7:$AG$7,"4",$D137:$BH137) -> 0 | BT137: =SUMIFS($D$9:$AG$9,$D$7:$AG$7,"4",$D137:$BH137,">"&-1) -> #VALUE! | BU137: =ROUNDUP(IF(BT137,BS137/BT137%,0),2) -> #VALUE! | BV137: =SUMIF($D$7:$AG$7,"5",$D137:$BH137) -> 0 | BW137: =SUMIFS($D$9:$AG$9,$D$7:$AG$7,"5",$D137:$BH137,">"&-1) -> #VALUE! | BX137: =ROUNDUP(IF(BW137,BV137/BW137%,0),2) -> #VALUE! | BY137: =SUMIF($D$7:$AG$7,"6",$D137:$BH137) -> 0 | BZ137: =SUMIFS($D$9:$AG$9,$D$7:$AG$7,"6",$D137:$BH137,">"&-1) -> #VALUE! | CA137: =ROUNDUP(IF(BZ137,BY137/BZ137%,0),2) -> #VALUE!
BG138: =SUM(D138:R138) -> 0 | BH138: =(BG138*15)/40 -> 0 | BJ138: =SUMIF($D$7:$AG$7,"1",$D138:$BH138) -> 0 | BK138: =SUMIFS($D$9:$AG$9,$D$7:$AG$7,"1",$D138:$BH138,">"&-1) -> #VALUE! | BL138: =ROUNDUP(IF(BK138,BJ138/BK138%,0),2) -> #VALUE! | BM138: =SUMIF($D$7:$AG$7,"2",$D138:$BH138) -> 0 | BN138: =SUMIFS($D$9:$AG$9,$D$7:$AG$7,"2",$D138:$BH138,">"&-1) -> #VALUE! | BO138: =ROUNDUP(IF(BN138,BM138/BN138%,0),2) -> #VALUE! | BP138: =SUMIF($D$7:$AG$7,"3",$D138:$BH138) -> 0 | BQ138: =SUMIFS($D$9:$AG$9,$D$7:$AG$7,"3",$D138:$BH138,">"&-1) -> #VALUE! | BR138: =ROUNDUP(IF(BQ138,BP138/BQ138%,0),2) -> #VALUE! | BS138: =SUMIF($D$7:$AG$7,"4",$D138:$BH138) -> 0 | BT138: =SUMIFS($D$9:$AG$9,$D$7:$AG$7,"4",$D138:$BH138,">"&-1) -> #VALUE! | BU138: =ROUNDUP(IF(BT138,BS138/BT138%,0),2) -> #VALUE! | BV138: =SUMIF($D$7:$AG$7,"5",$D138:$BH138) -> 0 | BW138: =SUMIFS($D$9:$AG$9,$D$7:$AG$7,"5",$D138:$BH138,">"&-1) -> #VALUE! | BX138: =ROUNDUP(IF(BW138,BV138/BW138%,0),2) -> #VALUE! | BY138: =SUMIF($D$7:$AG$7,"6",$D138:$BH138) -> 0 | BZ138: =SUMIFS($D$9:$AG$9,$D$7:$AG$7,"6",$D138:$BH138,">"&-1) -> #VALUE! | CA138: =ROUNDUP(IF(BZ138,BY138/BZ138%,0),2) -> #VALUE!
BG139: =SUM(D139:R139) -> 0 | BH139: =(BG139*15)/40 -> 0 | BJ139: =SUMIF($D$7:$AG$7,"1",$D139:$BH139) -> 0 | BK139: =SUMIFS($D$9:$AG$9,$D$7:$AG$7,"1",$D139:$BH139,">"&-1) -> #VALUE! | BL139: =ROUNDUP(IF(BK139,BJ139/BK139%,0),2) -> #VALUE! | BM139: =SUMIF($D$7:$AG$7,"2",$D139:$BH139) -> 0 | BN139: =SUMIFS($D$9:$AG$9,$D$7:$AG$7,"2",$D139:$BH139,">"&-1) -> #VALUE! | BO139: =ROUNDUP(IF(BN139,BM139/BN139%,0),2) -> #VALUE! | BP139: =SUMIF($D$7:$AG$7,"3",$D139:$BH139) -> 0 | BQ139: =SUMIFS($D$9:$AG$9,$D$7:$AG$7,"3",$D139:$BH139,">"&-1) -> #VALUE! | BR139: =ROUNDUP(IF(BQ139,BP139/BQ139%,0),2) -> #VALUE! | BS139: =SUMIF($D$7:$AG$7,"4",$D139:$BH139) -> 0 | BT139: =SUMIFS($D$9:$AG$9,$D$7:$AG$7,"4",$D139:$BH139,">"&-1) -> #VALUE! | BU139: =ROUNDUP(IF(BT139,BS139/BT139%,0),2) -> #VALUE! | BV139: =SUMIF($D$7:$AG$7,"5",$D139:$BH139) -> 0 | BW139: =SUMIFS($D$9:$AG$9,$D$7:$AG$7,"5",$D139:$BH139,">"&-1) -> #VALUE! | BX139: =ROUNDUP(IF(BW139,BV139/BW139%,0),2) -> #VALUE! | BY139: =SUMIF($D$7:$AG$7,"6",$D139:$BH139) -> 0 | BZ139: =SUMIFS($D$9:$AG$9,$D$7:$AG$7,"6",$D139:$BH139,">"&-1) -> #VALUE! | CA139: =ROUNDUP(IF(BZ139,BY139/BZ139%,0),2) -> #VALUE!
BG140: =SUM(D140:R140) -> 0 | BH140: =(BG140*15)/40 -> 0 | BJ140: =SUMIF($D$7:$AG$7,"1",$D140:$BH140) -> 0 | BK140: =SUMIFS($D$9:$AG$9,$D$7:$AG$7,"1",$D140:$BH140,">"&-1) -> #VALUE! | BL140: =ROUNDUP(IF(BK140,BJ140/BK140%,0),2) -> #VALUE! | BM140: =SUMIF($D$7:$AG$7,"2",$D140:$BH140) -> 0 | BN140: =SUMIFS($D$9:$AG$9,$D$7:$AG$7,"2",$D140:$BH140,">"&-1) -> #VALUE! | BO140: =ROUNDUP(IF(BN140,BM140/BN140%,0),2) -> #VALUE! | BP140: =SUMIF($D$7:$AG$7,"3",$D140:$BH140) -> 0 | BQ140: =SUMIFS($D$9:$AG$9,$D$7:$AG$7,"3",$D140:$BH140,">"&-1) -> #VALUE! | BR140: =ROUNDUP(IF(BQ140,BP140/BQ140%,0),2) -> #VALUE! | BS140: =SUMIF($D$7:$AG$7,"4",$D140:$BH140) -> 0 | BT140: =SUMIFS($D$9:$AG$9,$D$7:$AG$7,"4",$D140:$BH140,">"&-1) -> #VALUE! | BU140: =ROUNDUP(IF(BT140,BS140/BT140%,0),2) -> #VALUE! | BV140: =SUMIF($D$7:$AG$7,"5",$D140:$BH140) -> 0 | BW140: =SUMIFS($D$9:$AG$9,$D$7:$AG$7,"5",$D140:$BH140,">"&-1) -> #VALUE! | BX140: =ROUNDUP(IF(BW140,BV140/BW140%,0),2) -> #VALUE! | BY140: =SUMIF($D$7:$AG$7,"6",$D140:$BH140) -> 0 | BZ140: =SUMIFS($D$9:$AG$9,$D$7:$AG$7,"6",$D140:$BH140,">"&-1) -> #VALUE! | CA140: =ROUNDUP(IF(BZ140,BY140/BZ140%,0),2) -> #VALUE!
BG141: =SUM(D141:R141) -> 0 | BH141: =(BG141*15)/40 -> 0 | BJ141: =SUMIF($D$7:$AG$7,"1",$D141:$BH141) -> 0 | BK141: =SUMIFS($D$9:$AG$9,$D$7:$AG$7,"1",$D141:$BH141,">"&-1) -> #VALUE! | BL141: =ROUNDUP(IF(BK141,BJ141/BK141%,0),2) -> #VALUE! | BM141: =SUMIF($D$7:$AG$7,"2",$D141:$BH141) -> 0 | BN141: =SUMIFS($D$9:$AG$9,$D$7:$AG$7,"2",$D141:$BH141,">"&-1) -> #VALUE! | BO141: =ROUNDUP(IF(BN141,BM141/BN141%,0),2) -> #VALUE! | BP141: =SUMIF($D$7:$AG$7,"3",$D141:$BH141) -> 0 | BQ141: =SUMIFS($D$9:$AG$9,$D$7:$AG$7,"3",$D141:$BH141,">"&-1) -> #VALUE! | BR141: =ROUNDUP(IF(BQ141,BP141/BQ141%,0),2) -> #VALUE! | BS141: =SUMIF($D$7:$AG$7,"4",$D141:$BH141) -> 0 | BT141: =SUMIFS($D$9:$AG$9,$D$7:$AG$7,"4",$D141:$BH141,">"&-1) -> #VALUE! | BU141: =ROUNDUP(IF(BT141,BS141/BT141%,0),2) -> #VALUE! | BV141: =SUMIF($D$7:$AG$7,"5",$D141:$BH141) -> 0 | BW141: =SUMIFS($D$9:$AG$9,$D$7:$AG$7,"5",$D141:$BH141,">"&-1) -> #VALUE! | BX141: =ROUNDUP(IF(BW141,BV141/BW141%,0),2) -> #VALUE! | BY141: =SUMIF($D$7:$AG$7,"6",$D141:$BH141) -> 0 | BZ141: =SUMIFS($D$9:$AG$9,$D$7:$AG$7,"6",$D141:$BH141,">"&-1) -> #VALUE! | CA141: =ROUNDUP(IF(BZ141,BY141/BZ141%,0),2) -> #VALUE!
